<?xml version="1.0" encoding="utf-8"?>
<!-- =================================================================================== -->
<!-- |    This document was autogenerated by xacro from urdf/justina.xacro             | -->
<!-- |    EDITING THIS FILE BY HAND IS NOT RECOMMENDED                                 | -->
<!-- =================================================================================== -->
<robot name="justina">
  <!-- Import Rviz colors -->
  <material name="black">
    <color rgba="0.0 0.0 0.0 1.0"/>
  </material>
  <material name="blue">
    <color rgba="0.0 0.0 0.8 1.0"/>
  </material>
  <material name="green">
    <color rgba="0.0 0.8 0.0 1.0"/>
  </material>
  <material name="gray">
    <color rgba="0.2 0.2 0.2 1.0"/>
  </material>
  <material name="orange">
    <color rgba="1.0 0.423529411765 0.0392156862745 1.0"/>
  </material>
  <material name="brown">
    <color rgba="0.870588235294 0.811764705882 0.764705882353 1.0"/>
  </material>
  <material name="red">
    <color rgba="0.8 0.0 0.0 1.0"/>
  </material>
  <material name="white">
    <color rgba="1.0 1.0 1.0 1.0"/>
  </material>
  <gazebo reference="base_link">
    <material>Gazebo/Blue</material>
    <selfCollide>false</selfCollide>
    <gravity>true</gravity>
    <mu1>0.9</mu1>
    <mu2>0.9</mu2>
  </gazebo>
  <gazebo reference="wheel_left">
    <material>Gazebo/Black</material>
    <selfCollide>false</selfCollide>
    <gravity>true</gravity>
    <turnGravityOff>false</turnGravityOff>
    <kp>1000000.0</kp>
    <kd>10.0</kd>
    <mu1>1.0</mu1>
    <mu2>1.0</mu2>
    <fdir1>1 0 0</fdir1>
    <maxVel>1.0</maxVel>
    <minDepth>0.00</minDepth>
  </gazebo>
  <gazebo reference="wheel_right">
    <material>Gazebo/Black</material>
    <selfCollide>false</selfCollide>
    <gravity>true</gravity>
    <turnGravityOff>false</turnGravityOff>
    <kp>1000000.0</kp>
    <kd>10.0</kd>
    <mu1>1.0</mu1>
    <mu2>1.0</mu2>
    <fdir1>1 0 0</fdir1>
    <maxVel>1.0</maxVel>
    <minDepth>0.00</minDepth>
  </gazebo>
  <gazebo reference="wheel_back_y">
    <selfCollide>false</selfCollide>
    <gravity>true</gravity>
    <mu1>0.1</mu1>
    <mu2>0.1</mu2>
    <maxVel>1.0</maxVel>
    <material value="Gazebo/FlatBlack"/>
  </gazebo>
  <gazebo reference="wheel_front_z">
    <selfCollide>false</selfCollide>
    <gravity>true</gravity>
    <mu1>0.1</mu1>
    <mu2>0.1</mu2>
    <maxVel>1.0</maxVel>
    <material value="Gazebo/Black"/>
  </gazebo>
  <transmission name="tran1">
    <type>transmission_interface/SimpleTransmission</type>
    <joint name="wheel_left_connect">
      <hardwareInterface>hardware_interface/EffortJointInterface</hardwareInterface>
    </joint>
    <actuator name="motor1">
      <mechanicalReduction>1</mechanicalReduction>
    </actuator>
  </transmission>
  <transmission name="tran2">
    <type>transmission_interface/SimpleTransmission</type>
    <joint name="wheel_right_connect">
      <hardwareInterface>hardware_interface/EffortJointInterface</hardwareInterface>
    </joint>
    <actuator name="motor2">
      <mechanicalReduction>1</mechanicalReduction>
    </actuator>
  </transmission>
  <!-- GAZEBO DIFF CONTROL -->
  <gazebo>
    <plugin filename="libgazebo_ros_diff_drive.so" name="differential_drive_controller">
      <leftJoint>wheel_left_connect</leftJoint>
      <rightJoint>wheel_right_connect</rightJoint>
      <wheelSeparation>0.42</wheelSeparation>
      <wheelDiameter>0.12</wheelDiameter>
      <torque>20</torque>
      <publishWheelTF>true</publishWheelTF>
      <robotNamespace>/</robotNamespace>
      <publishTf>1</publishTf>
      <publishWheelJointState>false</publishWheelJointState>
      <alwaysOn>true</alwaysOn>
      <updateRate>100.0</updateRate>
      <broadcastTF>1</broadcastTF>
      <wheelTorque>20.0</wheelTorque>
      <commandTopic>cmd_vel</commandTopic>
      <odometryFrame>odom</odometryFrame>
      <odometryTopic>odom</odometryTopic>
      <pose_covariance_diagonal>[1.0, 1.0, 0.0, 0.0, 0.0, 1.0]</pose_covariance_diagonal>
      <twist_covariance_diagonal>[0.01, 0.0, 0.0, 0.0, 0.0, 0.1]</twist_covariance_diagonal>
      <gaussianNoise>0.05</gaussianNoise>
      <robotBaseFrame>base_link</robotBaseFrame>
      <legacyMode>false</legacyMode>
      <publishOdomTF>true</publishOdomTF>
      <odometrySource>world</odometrySource>
    </plugin>
  </gazebo>
  <!-- GAZEBO LASER SCAN  -->
  <gazebo reference="laser_link">
    <material value="Gazebo/Black"/>
    <sensor name="hokuyo_sensor" type="ray">
      <pose>0 0 0 0 0 0</pose>
      <visualize>true</visualize>
      <update_rate>10</update_rate>
      <ray>
        <scan>
          <horizontal>
            <samples>370</samples>
            <resolution>0.5</resolution>
            <min_angle>-1.570796</min_angle>
            <max_angle>1.570796</max_angle>
          </horizontal>
        </scan>
        <range>
          <min>0.10</min>
          <max>10.0</max>
          <resolution>0.01</resolution>
        </range>
        <noise>
          <type>gaussian</type>
          <mean>0.0</mean>
          <stddev>0.01</stddev>
        </noise>
      </ray>
      <plugin filename="libgazebo_ros_laser.so" name="gazebo_ros_hokuyo_controller">
        <topicName>/scan</topicName>
        <frameName>laser_link</frameName>
      </plugin>
    </sensor>
  </gazebo>
  <gazebo>
    <plugin filename="libgazebo_ros_control.so" name="ros_control">
      <robotNamespace>/</robotNamespace>
    </plugin>
  </gazebo>
  <!-- BASE LINKS AND JOINTS -->
  <link name="base_link">
    <visual>
      <origin rpy="0 0 0" xyz="0 0 0.235"/>
      <geometry>
        <box size="0.42 0.42 0.2"/>
      </geometry>
      <material name="blue"/>
    </visual>
    <collision>
      <origin rpy="0 0 0" xyz="0 0 0.235"/>
      <geometry>
        <box size="0.42 0.42 0.2"/>
      </geometry>
    </collision>
    <inertial>
      <origin rpy="0 0 0" xyz="0 0 0.235"/>
      <mass value="50.00"/>
      <inertia ixx="0.541" ixy="0" ixz="0" iyy="0.541" iyz="0" izz="0.541"/>
    </inertial>
  </link>
  <joint name="wheel_left_connect" type="continuous">
    <origin rpy="-1.570796327 0 0" xyz="0 0.24 0.065"/>
    <parent link="base_link"/>
    <child link="wheel_left"/>
    <axis xyz="0.0 0 1.0"/>
    <limit effort="11.067" velocity="20.8"/>
    <dynamics damping="1.0"/>
  </joint>
  <link name="wheel_left">
    <visual>
      <origin rpy="0 0 0" xyz="0 0 0"/>
      <geometry>
        <cylinder length="0.04" radius="0.06"/>
      </geometry>
      <material name="gray">
        <color rgba="0 0 0 1"/>
      </material>
    </visual>
    <collision>
      <origin rpy="0 0 0" xyz="0 0 0"/>
      <geometry>
        <cylinder length="0.04" radius="0.06"/>
      </geometry>
    </collision>
    <inertial>
      <origin xyz="0 0 0"/>
      <mass value="0.2"/>
      <inertia ixx="0.031" ixy="0" ixz="0" iyy="0.031" iyz="0" izz="0.054"/>
    </inertial>
  </link>
  <joint name="wheel_right_connect" type="continuous">
    <origin rpy="-1.5708 0 0" xyz="0 -0.24 0.065"/>
    <parent link="base_link"/>
    <child link="wheel_right"/>
    <axis xyz="0.0 0 1.0"/>
    <limit effort="11.067" velocity="20.8"/>
    <dynamics damping="1.0"/>
  </joint>
  <link name="wheel_right">
    <visual>
      <origin rpy="0 0 0" xyz="0 0 0"/>
      <geometry>
        <cylinder length="0.04" radius="0.06"/>
      </geometry>
      <material name="black">
        <color rgba="0 0 0 1"/>
      </material>
    </visual>
    <collision>
      <origin rpy="0 0 0" xyz="0 0 0"/>
      <geometry>
        <cylinder length="0.04" radius="0.06"/>
      </geometry>
    </collision>
    <inertial>
      <origin rpy="0 0 0" xyz="0 0 0"/>
      <mass value="0.2"/>
      <inertia ixx="0.031" ixy="0" ixz="0" iyy="0.031" iyz="0" izz="0.054"/>
    </inertial>
  </link>
  <joint name="wheel_back_connect_x" type="continuous">
    <origin rpy="-1.5708 0 -1.5708" xyz="-0.24 0 0.065"/>
    <parent link="base_link"/>
    <child link="wheel_back_x"/>
    <axis xyz="1 0 0"/>
    <limit effort="1.0" velocity="3.0"/>
    <dynamics damping="1.0"/>
  </joint>
  <link name="wheel_back_x">
    <inertial>
      <origin rpy="0 0 0" xyz="0 0 0"/>
      <mass value="0.2"/>
      <inertia ixx="0.015" ixy="0" ixz="0" iyy="0.015" iyz="0" izz="0.015"/>
    </inertial>
  </link>
  <joint name="wheel_back_connect_y" type="continuous">
    <axis xyz="0 1 0"/>
    <limit effort="8.85" velocity="10.0"/>
    <parent link="wheel_back_x"/>
    <child link="wheel_back_y"/>
  </joint>
  <link name="wheel_back_y">
    <inertial>
      <mass value="0.2"/>
      <origin xyz="0 0 0"/>
      <inertia ixx="0.015" ixy="0" ixz="0" iyy="0.015" iyz="0" izz="0.015"/>
    </inertial>
  </link>
  <joint name="wheel_back_connect_z" type="continuous">
    <axis xyz="0.0 0.0 1.0"/>
    <limit effort="8.85" velocity="10.0"/>
    <parent link="wheel_back_y"/>
    <child link="wheel_back_z"/>
  </joint>
  <link name="wheel_back_z">
    <visual>
      <geometry>
        <sphere radius="0.06"/>
      </geometry>
      <material name="wheel"/>
    </visual>
    <collision>
      <geometry>
        <sphere radius="0.06"/>
      </geometry>
    </collision>
    <inertial>
      <mass value="0.2"/>
      <origin xyz="0 0 0"/>
      <inertia ixx="0.015" ixy="0" ixz="0" iyy="0.015" iyz="0" izz="0.015"/>
    </inertial>
  </link>
  <joint name="wheel_front_connect_x" type="continuous">
    <origin rpy="-1.5708 0 -1.5708" xyz="0.24 0 0.065"/>
    <parent link="base_link"/>
    <child link="wheel_front_x"/>
    <axis xyz="1 0 0"/>
    <limit effort="1.0" velocity="3.0"/>
    <dynamics damping="1.0"/>
  </joint>
  <link name="wheel_front_x">
    <inertial>
      <mass value="0.2"/>
      <origin xyz="0 0 0"/>
      <inertia ixx="0.015" ixy="0" ixz="0" iyy="0.015" iyz="0" izz="0.015"/>
    </inertial>
  </link>
  <joint name="wheel_front_connect_y" type="continuous">
    <axis xyz="0.0 1.0 0.0"/>
    <limit effort="8.85" velocity="10.0"/>
    <parent link="wheel_front_x"/>
    <child link="wheel_front_y"/>
  </joint>
  <link name="wheel_front_y">
    <inertial>
      <mass value="0.2"/>
      <origin xyz="0 0 0"/>
      <inertia ixx="0.015" ixy="0" ixz="0" iyy="0.015" iyz="0" izz="0.015"/>
    </inertial>
  </link>
  <joint name="wheel_front_connect_z" type="continuous">
    <axis xyz="0.0 0.0 1.0"/>
    <limit effort="8.85" velocity="10.0"/>
    <parent link="wheel_front_y"/>
    <child link="wheel_front_z"/>
  </joint>
  <link name="wheel_front_z">
    <visual>
      <geometry>
        <sphere radius="0.06"/>
      </geometry>
      <material name="wheel"/>
    </visual>
    <collision>
      <geometry>
        <sphere radius="0.06"/>
      </geometry>
    </collision>
    <inertial>
      <mass value="0.2"/>
      <origin xyz="0 0 0"/>
      <inertia ixx="0.015" ixy="0" ixz="0" iyy="0.015" iyz="0" izz="0.015"/>
    </inertial>
  </link>
  <!-- LASER LINK AND JOINTS-->
  <link name="laser_link">
    <visual>
      <origin rpy="0 0 0" xyz="0 0 0"/>
      <geometry>
        <box size="0.08 0.08 0.1"/>
      </geometry>
      <material name="black"/>
    </visual>
    <collision>
      <origin rpy="0 0 0" xyz="0 0 0"/>
      <geometry>
        <box size="0.08 0.08 0.1"/>
      </geometry>
    </collision>
    <inertial>
      <origin rpy="0 0 0" xyz="0 0 0"/>
      <mass value="0.1"/>
      <inertia ixx="6.83333333333e-05" ixy="0" ixz="0" iyy="6.83333333333e-05" iyz="0" izz="6.83333333333e-05"/>
    </inertial>
  </link>
  <joint name="laser_connect" type="fixed">
    <origin xyz="0.1 0 0.44"/>
    <parent link="base_link"/>
    <child link="laser_link"/>
  </joint>
  <!--TORSO TRANSMISSIONS-->
  <transmission name="tran5">
    <type>transmission_interface/SimpleTransmission</type>
    <joint name="spine_connect">
      <hardwareInterface>hardware_interface/EffortJointInterface</hardwareInterface>
    </joint>
    <actuator name="motor5">
      <hardwareInterface>hardware_interface/EffortJointInterface</hardwareInterface>
      <mechanicalReduction>1</mechanicalReduction>
    </actuator>
  </transmission>
  <link name="torso_link">
    <collision>
      <origin rpy="1.5707 0 1.5707" xyz="0.04 -0.097 -0.55"/>
      <geometry>
        <mesh filename="package://justina_description/stl/torso.stl"/>
      </geometry>
    </collision>
    <visual>
      <origin rpy="1.5707 0 1.5707" xyz="0.04 -0.097 -0.55"/>
      <geometry>
        <mesh filename="package://justina_description/stl/torso.stl"/>
      </geometry>
      <material name="black_gray">
        <color rgba="0.2 0.2 0.2 1"/>
      </material>
    </visual>
    <inertial>
      <mass value="0.6"/>
      <origin rpy="0 0 0" xyz="0.04 -0.097 -0.55"/>
      <inertia ixx="0.01553" ixy="0" ixz="0" iyy="0.01537" iyz="0" izz="0.01537"/>
    </inertial>
  </link>
  <joint name="spine_connect" type="prismatic">
    <origin rpy="0 0 0" xyz="0.0 0 0.162"/>
    <parent link="torso_link"/>
    <child link="spine_link"/>
    <limit effort="1000" lower="0.2" upper="0.5" velocity="0.2"/>
    <axis xyz="0 0 1"/>
  </joint>
  <link name="spine_link">
    <collision>
      <origin rpy="0 0 1.5707" xyz="0.0 0 -0.5325"/>
      <geometry>
        <mesh filename="package://justina_description/stl/spine.stl"/>
      </geometry>
    </collision>
    <visual>
      <origin rpy="0 0 1.5707" xyz="0.0 0 -0.5325"/>
      <geometry>
        <mesh filename="package://justina_description/stl/spine.stl"/>
      </geometry>
      <material name="gray_white">
        <color rgba="0.6 0.6 0.6 1"/>
      </material>
    </visual>
    <inertial>
      <mass value="0.1"/>
      <origin rpy="0 0 0" xyz="0 0 -0.5325"/>
      <inertia ixx="0.0024975" ixy="0" ixz="0" iyy="0.00247083333333" iyz="0" izz="0.00247083333333"/>
    </inertial>
  </link>
  <!--LEFT ARM TRANSMISSIONS-->
  <transmission name="la_1_transmission">
    <type>transmission_interface/SimpleTransmission</type>
    <joint name="la_1_joint">
      <hardwareInterface>hardware_interface/EffortJointInterface</hardwareInterface>
    </joint>
    <actuator name="la_1_motor">
      <hardwareInterface>hardware_interface/EffortJointInterface</hardwareInterface>
      <mechanicalReduction>1</mechanicalReduction>
    </actuator>
  </transmission>
  <transmission name="la_2_transmission">
    <type>transmission_interface/SimpleTransmission</type>
    <joint name="la_2_joint">
      <hardwareInterface>hardware_interface/EffortJointInterface</hardwareInterface>
    </joint>
    <actuator name="la_2_motor">
      <hardwareInterface>hardware_interface/EffortJointInterface</hardwareInterface>
      <mechanicalReduction>1</mechanicalReduction>
    </actuator>
  </transmission>
  <transmission name="la_3_transmission">
    <type>transmission_interface/SimpleTransmission</type>
    <joint name="la_3_joint">
      <hardwareInterface>hardware_interface/EffortJointInterface</hardwareInterface>
    </joint>
    <actuator name="la_3_motor">
      <hardwareInterface>hardware_interface/EffortJointInterface</hardwareInterface>
      <mechanicalReduction>1</mechanicalReduction>
    </actuator>
  </transmission>
  <transmission name="la_4_transmission">
    <type>transmission_interface/SimpleTransmission</type>
    <joint name="la_4_joint">
      <hardwareInterface>hardware_interface/EffortJointInterface</hardwareInterface>
    </joint>
    <actuator name="la_4_motor">
      <hardwareInterface>hardware_interface/EffortJointInterface</hardwareInterface>
      <mechanicalReduction>1</mechanicalReduction>
    </actuator>
  </transmission>
  <transmission name="la_5_transmission">
    <type>transmission_interface/SimpleTransmission</type>
    <joint name="la_5_joint">
      <hardwareInterface>hardware_interface/EffortJointInterface</hardwareInterface>
    </joint>
    <actuator name="la_5_motor">
      <hardwareInterface>hardware_interface/EffortJointInterface</hardwareInterface>
      <mechanicalReduction>1</mechanicalReduction>
    </actuator>
  </transmission>
  <transmission name="la_6_transmission">
    <type>transmission_interface/SimpleTransmission</type>
    <joint name="la_6_joint">
      <hardwareInterface>hardware_interface/EffortJointInterface</hardwareInterface>
    </joint>
    <actuator name="la_6_motor">
      <hardwareInterface>hardware_interface/EffortJointInterface</hardwareInterface>
      <mechanicalReduction>1</mechanicalReduction>
    </actuator>
  </transmission>
  <transmission name="la_7_transmission">
    <type>transmission_interface/SimpleTransmission</type>
    <joint name="la_7_joint">
      <hardwareInterface>hardware_interface/EffortJointInterface</hardwareInterface>
    </joint>
    <actuator name="la_7_motor">
      <hardwareInterface>hardware_interface/EffortJointInterface</hardwareInterface>
      <mechanicalReduction>1</mechanicalReduction>
    </actuator>
  </transmission>
  <transmission name="la_grip_left_transmission">
    <type>transmission_interface/SimpleTransmission</type>
    <joint name="la_grip_left">
      <hardwareInterface>hardware_interface/EffortJointInterface</hardwareInterface>
    </joint>
    <actuator name="la_grip_left_motor">
      <hardwareInterface>hardware_interface/EffortJointInterface</hardwareInterface>
      <mechanicalReduction>1</mechanicalReduction>
    </actuator>
  </transmission>
  <transmission name="la_grip_right_transmission">
    <type>transmission_interface/SimpleTransmission</type>
    <joint name="la_grip_right">
      <hardwareInterface>hardware_interface/EffortJointInterface</hardwareInterface>
    </joint>
    <actuator name="la_grip_right_motor">
      <hardwareInterface>hardware_interface/EffortJointInterface</hardwareInterface>
      <mechanicalReduction>1</mechanicalReduction>
    </actuator>
  </transmission>
  <gazebo reference="shoulders_left_link">
    <material>Gazebo/Orange</material>
  </gazebo>
  <gazebo reference="left_arm_link1">
    <material>Gazebo/Orange</material>
  </gazebo>
  <gazebo reference="left_arm_link2">
    <material>Gazebo/Orange</material>
  </gazebo>
  <gazebo reference="left_arm_link3">
    <material>Gazebo/Orange</material>
  </gazebo>
  <gazebo reference="left_arm_link4">
    <material>Gazebo/Orange</material>
  </gazebo>
  <gazebo reference="left_arm_link5">
    <material>Gazebo/Orange</material>
  </gazebo>
  <gazebo reference="left_arm_link6">
    <material>Gazebo/Orange</material>
  </gazebo>
  <gazebo reference="left_arm_link7">
    <material>Gazebo/Orange</material>
  </gazebo>
  <gazebo reference="left_arm_grip_left">
    <material>Gazebo/Orange</material>
    <mu1>1</mu1>
    <mu2>1</mu2>
    <kp>1000000.0</kp>
    <kd>1.0</kd>
    <slip1>0</slip1>
    <slip2>0</slip2>
    <minDepth>0.001</minDepth>
    <maxVel>0</maxVel>
    <torsional>
      <ode>
        <coefficient>1000</coefficient>
        <slip>0</slip>
      </ode>
    </torsional>
  </gazebo>
  <gazebo reference="left_arm_grip_right">
    <material>Gazebo/Orange</material>
    <mu1>1</mu1>
    <mu2>1</mu2>
    <kp>1000000.0</kp>
    <kd>1.0</kd>
    <slip1>0</slip1>
    <slip2>0</slip2>
    <minDepth>0.001</minDepth>
    <maxVel>0</maxVel>
    <torsional>
      <ode>
        <coefficient>1000</coefficient>
        <slip>0</slip>
      </ode>
    </torsional>
  </gazebo>
  <!-- LEFT ARM LINKS AND JOINTS-->
  <link name="shoulders_left_link">
    <visual>
      <origin rpy="0 0 0" xyz="0 -0.01 0.02"/>
      <geometry>
        <box size="0.04025 0.108 0.065"/>
      </geometry>
      <material name="la_material">
        <color rgba="1.0 0.5 0 1"/>
      </material>
    </visual>
    <collision>
      <origin rpy="0 0 0" xyz="0 -0.01 0.02"/>
      <geometry>
        <box size="0.04025 0.108 0.065"/>
      </geometry>
    </collision>
    <inertial>
      <origin rpy="0 0 0" xyz="0 -0.01 0.02"/>
      <mass value="0.125"/>
      <inertia ixx="0.0015" ixy="0.0" ixz="0.0" iyy="0.002175" iyz="0.0" izz="0.003075"/>
    </inertial>
  </link>
  <link name="left_arm_link1">
    <visual>
      <origin rpy="0 0 0" xyz="0 -0.01 -0.04881"/>
      <geometry>
        <box size="0.04025 0.06 0.04025"/>
      </geometry>
      <material name="la_material">
        <color rgba="1.0 0.5 0 1"/>
      </material>
    </visual>
    <collision>
      <origin rpy="0 0 0" xyz="0 -0.01 -0.04881"/>
      <geometry>
        <box size="0.04025 0.06 0.04025"/>
      </geometry>
    </collision>
    <inertial>
      <origin rpy="0 0 0" xyz="0 -0.01 -0.04881"/>
      <mass value="0.125"/>
      <inertia ixx="0.0015" ixy="0.0" ixz="0.0" iyy="0.002175" iyz="0.0" izz="0.003075"/>
    </inertial>
  </link>
  <link name="left_arm_link2">
    <visual>
      <origin rpy="0 0 0" xyz="0 0 -0.125"/>
      <geometry>
        <box size="0.04025 0.04025 0.19"/>
      </geometry>
      <material name="la_material">
        <color rgba="1.0 0.5 0 1"/>
      </material>
    </visual>
    <visual>
      <origin rpy="0 0 0" xyz="-0.01 0 -0.197"/>
      <geometry>
        <box size="0.06 0.04025 0.04025"/>
      </geometry>
      <material name="la_material">
        <color rgba="1.0 0.5 0 1"/>
      </material>
    </visual>
    <collision>
      <origin rpy="0 0 0" xyz="0 0 -0.125"/>
      <geometry>
        <box size="0.04025 0.04025 0.19"/>
      </geometry>
    </collision>
    <collision>
      <origin rpy="0 0 0" xyz="-0.01 0 -0.197"/>
      <geometry>
        <box size="0.06 0.04025 0.04025"/>
      </geometry>
    </collision>
    <inertial>
      <origin rpy="0 0 0" xyz="0 0 -0.175"/>
      <mass value="0.155"/>
      <inertia ixx="0.0015" ixy="0.0" ixz="0.0" iyy="0.002175" iyz="0.0" izz="0.003075"/>
    </inertial>
  </link>
  <link name="left_arm_link3">
    <visual>
      <origin rpy="0 0 0" xyz="0 0 -0.04"/>
      <geometry>
        <box size="0.04025 0.04025 0.06"/>
      </geometry>
      <material name="la_material">
        <color rgba="1.0 0.5 0 1"/>
      </material>
    </visual>
    <collision>
      <origin rpy="0 0 0" xyz="0 0 -0.04"/>
      <geometry>
        <box size="0.04025 0.04025 0.06"/>
      </geometry>
    </collision>
    <inertial>
      <origin rpy="0 0 0" xyz="0 0 -0.04"/>
      <mass value="0.125"/>
      <inertia ixx="0.0015" ixy="0.0" ixz="0.0" iyy="0.002175" iyz="0.0" izz="0.003075"/>
    </inertial>
  </link>
  <link name="left_arm_link4">
    <visual>
      <origin rpy="0 0 0" xyz="0 0 -0.11"/>
      <geometry>
        <box size="0.04025 0.04025 0.16"/>
      </geometry>
      <material name="la_material">
        <color rgba="1.0 0.5 0 1"/>
      </material>
    </visual>
    <visual>
      <origin rpy="0 0 0" xyz="-0.01 0 -0.167"/>
      <geometry>
        <box size="0.06 0.04025 0.04025"/>
      </geometry>
      <material name="la_material">
        <color rgba="1.0 0.5 0 1"/>
      </material>
    </visual>
    <collision>
      <origin rpy="0 0 0" xyz="0 0 -0.11"/>
      <geometry>
        <box size="0.04025 0.04025 0.16"/>
      </geometry>
    </collision>
    <collision>
      <origin rpy="0 0 0" xyz="-0.01 0 -0.167"/>
      <geometry>
        <box size="0.06 0.04025 0.04025"/>
      </geometry>
    </collision>
    <inertial>
      <origin rpy="0 0 0" xyz="-0.01 0 -0.147"/>
      <mass value="0.125"/>
      <inertia ixx="0.0015" ixy="0.0" ixz="0.0" iyy="0.002175" iyz="0.0" izz="0.003075"/>
    </inertial>
  </link>
  <link name="left_arm_link5">
    <visual>
      <origin rpy="0 0 0" xyz="0 0 -0.025"/>
      <geometry>
        <box size="0.04025 0.04025 0.02"/>
      </geometry>
      <material name="la_material">
        <color rgba="1.0 0.5 0 1"/>
      </material>
    </visual>
    <collision>
      <origin rpy="0 0 0" xyz="0 0 -0.025"/>
      <geometry>
        <box size="0.04025 0.04025 0.02"/>
      </geometry>
    </collision>
    <inertial>
      <origin rpy="0 0 0" xyz="0 0 -0.025"/>
      <mass value="0.125"/>
      <inertia ixx="0.0015" ixy="0.0" ixz="0.0" iyy="0.002175" iyz="0.0" izz="0.003075"/>
    </inertial>
  </link>
  <link name="left_arm_link6">
    <visual>
      <origin rpy="0 0 0" xyz="0 0 -0.042"/>
      <geometry>
        <box size="0.04025 0.04025 0.04"/>
      </geometry>
      <material name="la_material">
        <color rgba="1.0 0.5 0 1"/>
      </material>
    </visual>
    <collision>
      <origin rpy="0 0 0" xyz="0 0 -0.042"/>
      <geometry>
        <box size="0.04025 0.04025 0.04"/>
      </geometry>
    </collision>
    <inertial>
      <origin rpy="0 0 0" xyz="0 0 -0.042"/>
      <mass value="0.125"/>
      <inertia ixx="0.0015" ixy="0.0" ixz="0.0" iyy="0.002175" iyz="0.0" izz="0.003075"/>
    </inertial>
  </link>
  <link name="left_arm_link7">
    <visual>
      <origin rpy="0 0 0" xyz="-0.01 0 -0.03"/>
      <geometry>
        <box size="0.06 0.03525 0.03525"/>
      </geometry>
      <material name="la_material">
        <color rgba="1.0 0.5 0 1"/>
      </material>
    </visual>
    <visual>
      <origin rpy="0 0 0" xyz="0 0 -0.055"/>
      <geometry>
        <box size="0.03 0.1 0.03"/>
      </geometry>
      <material name="la_material">
        <color rgba="1.0 0.5 0 1"/>
      </material>
    </visual>
    <collision>
      <origin rpy="0 0 0" xyz="-0.01 0 -0.03"/>
      <geometry>
        <box size="0.06 0.03525 0.03525"/>
      </geometry>
    </collision>
    <collision>
      <origin rpy="0 0 0" xyz="0 0 -0.055"/>
      <geometry>
        <box size="0.03 0.1 0.03"/>
      </geometry>
    </collision>
    <inertial>
      <origin rpy="0 0 0" xyz="-0.01 0 -0.05"/>
      <mass value="0.125"/>
      <inertia ixx="0.0015" ixy="0.0" ixz="0.0" iyy="0.002175" iyz="0.0" izz="0.003075"/>
    </inertial>
  </link>
  <link name="left_arm_grip_left">
    <visual>
      <origin rpy="0 0 0" xyz="0 0 -0.065"/>
      <geometry>
        <box size="0.04 0.005 0.09"/>
      </geometry>
      <material name="la_material">
        <color rgba="1.0 0.5 0 1"/>
      </material>
    </visual>
    <collision>
      <origin rpy="0 0 0" xyz="0 0 -0.065"/>
      <geometry>
        <box size="0.04 0.005 0.09"/>
      </geometry>
    </collision>
    <inertial>
      <origin rpy="0 0 0" xyz="0 0 -0.065"/>
      <mass value="0.125"/>
      <inertia ixx="0.0015" ixy="0.0" ixz="0.0" iyy="0.002175" iyz="0.0" izz="0.003075"/>
    </inertial>
  </link>
  <link name="left_arm_grip_right">
    <visual>
      <origin rpy="0 0 0" xyz="0 0 -0.065"/>
      <geometry>
        <box size="0.04 0.005 0.09"/>
      </geometry>
      <material name="la_material">
        <color rgba="1.0 0.5 0 1"/>
      </material>
    </visual>
    <collision>
      <origin rpy="0 0 0" xyz="0 0 -0.065"/>
      <geometry>
        <box size="0.04 0.005 0.09"/>
      </geometry>
    </collision>
    <inertial>
      <origin rpy="0 0 0" xyz="0 0 -0.065"/>
      <mass value="0.125"/>
      <inertia ixx="0.0015" ixy="0.0" ixz="0.0" iyy="0.002175" iyz="0.0" izz="0.003075"/>
    </inertial>
  </link>
  <link name="left_arm_grip_center"/>
  <joint name="la_1_joint" type="revolute">
    <origin rpy="0 0 0" xyz="0 0.0 0"/>
    <parent link="shoulders_left_link"/>
    <child link="left_arm_link1"/>
    <axis xyz="0 -1 0"/>
    <dynamics damping="0.1"/>
    <limit effort="16.0" lower="-1.7" upper="1.7" velocity="3.0"/>
  </joint>
  <joint name="la_2_joint" type="revolute">
    <origin rpy="0 0 0" xyz="0 0.0 -0.06381"/>
    <parent link="left_arm_link1"/>
    <child link="left_arm_link2"/>
    <axis xyz="1 0 0"/>
    <dynamics damping="0.1"/>
    <limit effort="8.0" lower="-0.75" upper="1.85" velocity="3.0"/>
  </joint>
  <joint name="la_3_joint" type="revolute">
    <origin rpy="0 0 0" xyz="0 0.0 -0.215"/>
    <parent link="left_arm_link2"/>
    <child link="left_arm_link3"/>
    <axis xyz="0 0 1"/>
    <dynamics damping="0.1"/>
    <limit effort="6.0" lower="-2.5" upper="2.5" velocity="3.0"/>
  </joint>
  <joint name="la_4_joint" type="revolute">
    <origin rpy="0 0 0" xyz="0 0.0 -0.065"/>
    <parent link="left_arm_link3"/>
    <child link="left_arm_link4"/>
    <axis xyz="0 -1 0"/>
    <dynamics damping="0.1"/>
    <limit effort="8.0" lower="-0.5" upper="2.5" velocity="3.0"/>
  </joint>
  <joint name="la_5_joint" type="revolute">
    <origin rpy="0 0 0" xyz="0 0.0 -0.18"/>
    <parent link="left_arm_link4"/>
    <child link="left_arm_link5"/>
    <axis xyz="0 0 1"/>
    <dynamics damping="0.1"/>
    <limit effort="6.0" lower="-2.5" upper="2.5" velocity="3.0"/>
  </joint>
  <joint name="la_6_joint" type="revolute">
    <origin rpy="0 0 0" xyz="0 0.0 -0.03"/>
    <parent link="left_arm_link5"/>
    <child link="left_arm_link6"/>
    <axis xyz="0 -1 0"/>
    <dynamics damping="0.1"/>
    <limit effort="6.0" lower="-1.4" upper="2.0" velocity="3.0"/>
  </joint>
  <joint name="la_7_joint" type="revolute">
    <origin rpy="0 0 0" xyz="0 0.0 -0.055"/>
    <parent link="left_arm_link6"/>
    <child link="left_arm_link7"/>
    <axis xyz="0 0 1"/>
    <dynamics damping="0.1"/>
    <limit effort="3.0" lower="-2.5" upper="2.5" velocity="3.0"/>
  </joint>
  <joint name="la_grip_left" type="revolute">
    <origin rpy="0 0 0" xyz="0 0.04 -0.06"/>
    <parent link="left_arm_link7"/>
    <child link="left_arm_grip_left"/>
    <axis xyz="1 0 0"/>
    <dynamics damping="0.1"/>
    <limit effort="3.0" lower="-0.3" upper="1.5" velocity="3.0"/>
  </joint>
  <joint name="la_grip_right" type="revolute">
    <origin rpy="0 0 0" xyz="0 -0.04 -0.06"/>
    <parent link="left_arm_link7"/>
    <child link="left_arm_grip_right"/>
    <axis xyz="-1 0 0"/>
    <dynamics damping="0.1"/>
    <limit effort="3.0" lower="-0.3" upper="1.5" velocity="3.0"/>
  </joint>
  <joint name="la_grip_center_joint" type="fixed">
    <origin rpy="0 0 0" xyz="0 0 -0.13"/>
    <parent link="left_arm_link7"/>
    <child link="left_arm_grip_center"/>
  </joint>
  <!--RIGHT ARM TRANSMISSIONS-->
  <transmission name="ra_1_transmission">
    <type>transmission_interface/SimpleTransmission</type>
    <joint name="ra_1_joint">
      <hardwareInterface>hardware_interface/EffortJointInterface</hardwareInterface>
    </joint>
    <actuator name="ra_1_motor">
      <hardwareInterface>hardware_interface/EffortJointInterface</hardwareInterface>
      <mechanicalReduction>1</mechanicalReduction>
    </actuator>
  </transmission>
  <transmission name="ra_2_transmission">
    <type>transmission_interface/SimpleTransmission</type>
    <joint name="ra_2_joint">
      <hardwareInterface>hardware_interface/EffortJointInterface</hardwareInterface>
    </joint>
    <actuator name="ra_2_motor">
      <hardwareInterface>hardware_interface/EffortJointInterface</hardwareInterface>
      <mechanicalReduction>1</mechanicalReduction>
    </actuator>
  </transmission>
  <transmission name="ra_3_transmission">
    <type>transmission_interface/SimpleTransmission</type>
    <joint name="ra_3_joint">
      <hardwareInterface>hardware_interface/EffortJointInterface</hardwareInterface>
    </joint>
    <actuator name="ra_3_motor">
      <hardwareInterface>hardware_interface/EffortJointInterface</hardwareInterface>
      <mechanicalReduction>1</mechanicalReduction>
    </actuator>
  </transmission>
  <transmission name="ra_4_transmission">
    <type>transmission_interface/SimpleTransmission</type>
    <joint name="ra_4_joint">
      <hardwareInterface>hardware_interface/EffortJointInterface</hardwareInterface>
    </joint>
    <actuator name="ra_4_motor">
      <hardwareInterface>hardware_interface/EffortJointInterface</hardwareInterface>
      <mechanicalReduction>1</mechanicalReduction>
    </actuator>
  </transmission>
  <transmission name="ra_5_transmission">
    <type>transmission_interface/SimpleTransmission</type>
    <joint name="ra_5_joint">
      <hardwareInterface>hardware_interface/EffortJointInterface</hardwareInterface>
    </joint>
    <actuator name="ra_5_motor">
      <hardwareInterface>hardware_interface/EffortJointInterface</hardwareInterface>
      <mechanicalReduction>1</mechanicalReduction>
    </actuator>
  </transmission>
  <transmission name="ra_6_transmission">
    <type>transmission_interface/SimpleTransmission</type>
    <joint name="ra_6_joint">
      <hardwareInterface>hardware_interface/EffortJointInterface</hardwareInterface>
    </joint>
    <actuator name="ra_6_motor">
      <hardwareInterface>hardware_interface/EffortJointInterface</hardwareInterface>
      <mechanicalReduction>1</mechanicalReduction>
    </actuator>
  </transmission>
  <transmission name="ra_7_transmission">
    <type>transmission_interface/SimpleTransmission</type>
    <joint name="ra_7_joint">
      <hardwareInterface>hardware_interface/EffortJointInterface</hardwareInterface>
    </joint>
    <actuator name="ra_7_motor">
      <hardwareInterface>hardware_interface/EffortJointInterface</hardwareInterface>
      <mechanicalReduction>1</mechanicalReduction>
    </actuator>
  </transmission>
  <transmission name="ra_grip_left_transmission">
    <type>transmission_interface/SimpleTransmission</type>
    <joint name="ra_grip_left">
      <hardwareInterface>hardware_interface/EffortJointInterface</hardwareInterface>
    </joint>
    <actuator name="ra_grip_left_motor">
      <hardwareInterface>hardware_interface/EffortJointInterface</hardwareInterface>
      <mechanicalReduction>1</mechanicalReduction>
    </actuator>
  </transmission>
  <transmission name="ra_grip_right_transmission">
    <type>transmission_interface/SimpleTransmission</type>
    <joint name="ra_grip_right">
      <hardwareInterface>hardware_interface/EffortJointInterface</hardwareInterface>
    </joint>
    <actuator name="ra_grip_right_motor">
      <hardwareInterface>hardware_interface/EffortJointInterface</hardwareInterface>
      <mechanicalReduction>1</mechanicalReduction>
    </actuator>
  </transmission>
  <gazebo reference="shoulders_right_link">
    <material>Gazebo/Orange</material>
  </gazebo>
  <gazebo reference="right_arm_link1">
    <material>Gazebo/Orange</material>
  </gazebo>
  <gazebo reference="right_arm_link2">
    <material>Gazebo/Orange</material>
  </gazebo>
  <gazebo reference="right_arm_link3">
    <material>Gazebo/Orange</material>
  </gazebo>
  <gazebo reference="right_arm_link4">
    <material>Gazebo/Orange</material>
  </gazebo>
  <gazebo reference="right_arm_link5">
    <material>Gazebo/Orange</material>
  </gazebo>
  <gazebo reference="right_arm_link6">
    <material>Gazebo/Orange</material>
  </gazebo>
  <gazebo reference="right_arm_link7">
    <material>Gazebo/Orange</material>
  </gazebo>
  <gazebo reference="right_arm_grip_left">
    <material>Gazebo/Orange</material>
    <mu1>1</mu1>
    <mu2>1</mu2>
    <kp>1000000.0</kp>
    <kd>1.0</kd>
    <slip1>0</slip1>
    <slip2>0</slip2>
    <minDepth>0.001</minDepth>
    <maxVel>0</maxVel>
    <torsional>
      <ode>
        <coefficient>1000</coefficient>
        <slip>0</slip>
      </ode>
    </torsional>
  </gazebo>
  <gazebo reference="right_arm_grip_right">
    <material>Gazebo/Orange</material>
    <mu1>1</mu1>
    <mu2>1</mu2>
    <kp>1000000.0</kp>
    <kd>1.0</kd>
    <slip1>0</slip1>
    <slip2>0</slip2>
    <minDepth>0.001</minDepth>
    <maxVel>0</maxVel>
    <torsional>
      <ode>
        <coefficient>1000</coefficient>
        <slip>0</slip>
      </ode>
    </torsional>
  </gazebo>
  <!--RIGHT ARM LINKS AND JOINTS-->
  <link name="shoulders_right_link">
    <visual>
      <origin rpy="0 0 0" xyz="0 0.01 0.02"/>
      <geometry>
        <box size="0.04025 0.108 0.065"/>
      </geometry>
      <material name="ra_material">
        <color rgba="1.0 0.5 0 1"/>
      </material>
    </visual>
    <collision>
      <origin rpy="0 0 0" xyz="0 0.01 0.02"/>
      <geometry>
        <box size="0.04025 0.108 0.065"/>
      </geometry>
    </collision>
    <inertial>
      <origin rpy="0 0 0" xyz="0 0.01 0.02"/>
      <mass value="0.125"/>
      <inertia ixx="0.0015" ixy="0.0" ixz="0.0" iyy="0.002175" iyz="0.0" izz="0.003075"/>
    </inertial>
  </link>
  <link name="right_arm_link1">
    <visual>
      <origin rpy="0 0 0" xyz="0 0.01 -0.04881"/>
      <geometry>
        <box size="0.04025 0.06 0.04025"/>
      </geometry>
      <material name="ra_material">
        <color rgba="1.0 0.5 0 1"/>
      </material>
    </visual>
    <collision>
      <origin rpy="0 0 0" xyz="0 0.01 -0.04881"/>
      <geometry>
        <box size="0.04025 0.06 0.04025"/>
      </geometry>
    </collision>
    <inertial>
      <origin rpy="0 0 0" xyz="0 0.01 -0.04881"/>
      <mass value="0.125"/>
      <inertia ixx="0.0015" ixy="0.0" ixz="0.0" iyy="0.002175" iyz="0.0" izz="0.003075"/>
    </inertial>
  </link>
  <link name="right_arm_link2">
    <visual>
      <origin rpy="0 0 0" xyz="0 0 -0.125"/>
      <geometry>
        <box size="0.04025 0.04025 0.19"/>
      </geometry>
      <material name="ra_material">
        <color rgba="1.0 0.5 0 1"/>
      </material>
    </visual>
    <visual>
      <origin rpy="0 0 0" xyz="-0.01 0 -0.197"/>
      <geometry>
        <box size="0.06 0.04025 0.04025"/>
      </geometry>
      <material name="la_material">
        <color rgba="1.0 0.5 0 1"/>
      </material>
    </visual>
    <collision>
      <origin rpy="0 0 0" xyz="0 0 -0.125"/>
      <geometry>
        <box size="0.04025 0.04025 0.19"/>
      </geometry>
    </collision>
    <collision>
      <origin rpy="0 0 0" xyz="-0.01 0 -0.197"/>
      <geometry>
        <box size="0.06 0.04025 0.04025"/>
      </geometry>
    </collision>
    <inertial>
      <origin rpy="0 0 0" xyz="0 0 -0.175"/>
      <mass value="0.155"/>
      <inertia ixx="0.0015" ixy="0.0" ixz="0.0" iyy="0.002175" iyz="0.0" izz="0.003075"/>
    </inertial>
  </link>
  <link name="right_arm_link3">
    <visual>
      <origin rpy="0 0 0" xyz="0 0 -0.04"/>
      <geometry>
        <box size="0.04025 0.04025 0.06"/>
      </geometry>
      <material name="ra_material">
        <color rgba="1.0 0.5 0 1"/>
      </material>
    </visual>
    <collision>
      <origin rpy="0 0 0" xyz="0 0 -0.04"/>
      <geometry>
        <box size="0.04025 0.04025 0.06"/>
      </geometry>
    </collision>
    <inertial>
      <origin rpy="0 0 0" xyz="0 0 -0.04"/>
      <mass value="0.125"/>
      <inertia ixx="0.0015" ixy="0.0" ixz="0.0" iyy="0.002175" iyz="0.0" izz="0.003075"/>
    </inertial>
  </link>
  <link name="right_arm_link4">
    <visual>
      <origin rpy="0 0 0" xyz="0 0 -0.11"/>
      <geometry>
        <box size="0.04025 0.04025 0.16"/>
      </geometry>
      <material name="ra_material">
        <color rgba="1.0 0.5 0 1"/>
      </material>
    </visual>
    <visual>
      <origin rpy="0 0 0" xyz="-0.01 0 -0.167"/>
      <geometry>
        <box size="0.06 0.04025 0.04025"/>
      </geometry>
      <material name="la_material">
        <color rgba="1.0 0.5 0 1"/>
      </material>
    </visual>
    <collision>
      <origin rpy="0 0 0" xyz="0 0 -0.11"/>
      <geometry>
        <box size="0.04025 0.04025 0.16"/>
      </geometry>
    </collision>
    <collision>
      <origin rpy="0 0 0" xyz="-0.01 0 -0.167"/>
      <geometry>
        <box size="0.06 0.04025 0.04025"/>
      </geometry>
    </collision>
    <inertial>
      <origin rpy="0 0 0" xyz="-0.01 0 -0.147"/>
      <mass value="0.125"/>
      <inertia ixx="0.0015" ixy="0.0" ixz="0.0" iyy="0.002175" iyz="0.0" izz="0.003075"/>
    </inertial>
  </link>
  <link name="right_arm_link5">
    <visual>
      <origin rpy="0 0 0" xyz="0 0 -0.025"/>
      <geometry>
        <box size="0.04025 0.04025 0.02"/>
      </geometry>
      <material name="ra_material">
        <color rgba="1.0 0.5 0 1"/>
      </material>
    </visual>
    <collision>
      <origin rpy="0 0 0" xyz="0 0 -0.025"/>
      <geometry>
        <box size="0.04025 0.04025 0.02"/>
      </geometry>
    </collision>
    <inertial>
      <origin rpy="0 0 0" xyz="0 0 -0.025"/>
      <mass value="0.125"/>
      <inertia ixx="0.0015" ixy="0.0" ixz="0.0" iyy="0.002175" iyz="0.0" izz="0.003075"/>
    </inertial>
  </link>
  <link name="right_arm_link6">
    <visual>
      <origin rpy="0 0 0" xyz="0 0 -0.042"/>
      <geometry>
        <box size="0.04025 0.04025 0.04"/>
      </geometry>
      <material name="ra_material">
        <color rgba="1.0 0.5 0 1"/>
      </material>
    </visual>
    <collision>
      <origin rpy="0 0 0" xyz="0 0 -0.042"/>
      <geometry>
        <box size="0.04025 0.04025 0.04"/>
      </geometry>
    </collision>
    <inertial>
      <origin rpy="0 0 0" xyz="0 0 -0.042"/>
      <mass value="0.125"/>
      <inertia ixx="0.0015" ixy="0.0" ixz="0.0" iyy="0.002175" iyz="0.0" izz="0.003075"/>
    </inertial>
  </link>
  <link name="right_arm_link7">
    <visual>
      <origin rpy="0 0 0" xyz="-0.01 0 -0.03"/>
      <geometry>
        <box size="0.06 0.03525 0.03525"/>
      </geometry>
      <material name="ra_material">
        <color rgba="1.0 0.5 0 1"/>
      </material>
    </visual>
    <visual>
      <origin rpy="0 0 0" xyz="0 0 -0.055"/>
      <geometry>
        <box size="0.03 0.1 0.03"/>
      </geometry>
      <material name="ra_material">
        <color rgba="1.0 0.5 0 1"/>
      </material>
    </visual>
    <collision>
      <origin rpy="0 0 0" xyz="-0.01 0 -0.03"/>
      <geometry>
        <box size="0.06 0.03525 0.03525"/>
      </geometry>
    </collision>
    <collision>
      <origin rpy="0 0 0" xyz="0 0 -0.055"/>
      <geometry>
        <box size="0.03 0.1 0.03"/>
      </geometry>
    </collision>
    <inertial>
      <origin rpy="0 0 0" xyz="-0.01 0 -0.05"/>
      <mass value="0.125"/>
      <inertia ixx="0.0015" ixy="0.0" ixz="0.0" iyy="0.002175" iyz="0.0" izz="0.003075"/>
    </inertial>
  </link>
  <link name="right_arm_grip_left">
    <visual>
      <origin rpy="0 0 0" xyz="0 0 -0.065"/>
      <geometry>
        <box size="0.04 0.005 0.09"/>
      </geometry>
      <material name="ra_material">
        <color rgba="1.0 0.5 0 1"/>
      </material>
    </visual>
    <collision>
      <origin rpy="0 0 0" xyz="0 0 -0.065"/>
      <geometry>
        <box size="0.04 0.005 0.09"/>
      </geometry>
    </collision>
    <inertial>
      <origin rpy="0 0 0" xyz="0 0 -0.065"/>
      <mass value="0.125"/>
      <inertia ixx="0.0015" ixy="0.0" ixz="0.0" iyy="0.002175" iyz="0.0" izz="0.003075"/>
    </inertial>
  </link>
  <link name="right_arm_grip_right">
    <visual>
      <origin rpy="0 0 0" xyz="0 0 -0.065"/>
      <geometry>
        <box size="0.04 0.005 0.09"/>
      </geometry>
      <material name="ra_material">
        <color rgba="1.0 0.5 0 1"/>
      </material>
    </visual>
    <collision>
      <origin rpy="0 0 0" xyz="0 0 -0.065"/>
      <geometry>
        <box size="0.04 0.005 0.09"/>
      </geometry>
    </collision>
    <inertial>
      <origin rpy="0 0 0" xyz="0 0 -0.065"/>
      <mass value="0.125"/>
      <inertia ixx="0.0015" ixy="0.0" ixz="0.0" iyy="0.002175" iyz="0.0" izz="0.003075"/>
    </inertial>
  </link>
  <link name="right_arm_grip_center"/>
  <joint name="ra_1_joint" type="revolute">
    <origin rpy="0 0 0" xyz="0 0.0 0"/>
    <parent link="shoulders_right_link"/>
    <child link="right_arm_link1"/>
    <axis xyz="0 -1 0"/>
    <dynamics damping="0.1"/>
    <limit effort="16.0" lower="-1.7" upper="1.7" velocity="3.0"/>
  </joint>
  <joint name="ra_2_joint" type="revolute">
    <origin rpy="0 0 0" xyz="0 0.0 -0.06381"/>
    <parent link="right_arm_link1"/>
    <child link="right_arm_link2"/>
    <axis xyz="1 0 0"/>
    <dynamics damping="0.1"/>
    <limit effort="8.0" lower="-1.85" upper="0.75" velocity="3.0"/>
  </joint>
  <joint name="ra_3_joint" type="revolute">
    <origin rpy="0 0 0" xyz="0 0.0 -0.215"/>
    <parent link="right_arm_link2"/>
    <child link="right_arm_link3"/>
    <axis xyz="0 0 1"/>
    <dynamics damping="0.1"/>
    <limit effort="6.0" lower="-2.5" upper="2.5" velocity="3.0"/>
  </joint>
  <joint name="ra_4_joint" type="revolute">
    <origin rpy="0 0 0" xyz="0 0.0 -0.065"/>
    <parent link="right_arm_link3"/>
    <child link="right_arm_link4"/>
    <axis xyz="0 -1 0"/>
    <dynamics damping="0.1"/>
    <limit effort="8.0" lower="-1.8" upper="1.8" velocity="3.0"/>
  </joint>
  <joint name="ra_5_joint" type="revolute">
    <origin rpy="0 0 0" xyz="0 0.0 -0.18"/>
    <parent link="right_arm_link4"/>
    <child link="right_arm_link5"/>
    <axis xyz="0 0 1"/>
    <dynamics damping="0.1"/>
    <limit effort="6.0" lower="-2.5" upper="2.5" velocity="3.0"/>
  </joint>
  <joint name="ra_6_joint" type="revolute">
    <origin rpy="0 0 0" xyz="0 0.0 -0.03"/>
    <parent link="right_arm_link5"/>
    <child link="right_arm_link6"/>
    <axis xyz="0 -1 0"/>
    <dynamics damping="0.1"/>
    <limit effort="6.0" lower="-1.4" upper="1.57" velocity="3.0"/>
  </joint>
  <joint name="ra_7_joint" type="revolute">
    <origin rpy="0 0 0" xyz="0 0.0 -0.055"/>
    <parent link="right_arm_link6"/>
    <child link="right_arm_link7"/>
    <axis xyz="0 0 1"/>
    <dynamics damping="0.1"/>
    <limit effort="3.0" lower="-2.5" upper="2.5" velocity="3.0"/>
  </joint>
  <joint name="ra_grip_left" type="revolute">
    <origin rpy="0 0 0" xyz="0 0.04 -0.06"/>
    <parent link="right_arm_link7"/>
    <child link="right_arm_grip_left"/>
    <axis xyz="1 0 0"/>
    <dynamics damping="0.1"/>
    <limit effort="3.0" lower="-0.3" upper="1.5" velocity="3.0"/>
  </joint>
  <joint name="ra_grip_right" type="revolute">
    <origin rpy="0 0 0" xyz="0 -0.04 -0.06"/>
    <parent link="right_arm_link7"/>
    <child link="right_arm_grip_right"/>
    <axis xyz="-1 0 0"/>
    <dynamics damping="0.1"/>
    <limit effort="3.0" lower="-0.3" upper="1.5" velocity="3.0"/>
  </joint>
  <joint name="ra_grip_center_joint" type="fixed">
    <origin rpy="0 0 0" xyz="0 0 -0.13"/>
    <parent link="right_arm_link7"/>
    <child link="right_arm_grip_center"/>
  </joint>
  <!--HEAD TRANSMISSIONS-->
  <transmission name="head_pan_transmission">
    <type>transmission_interface/SimpleTransmission</type>
    <joint name="head_pan">
      <hardwareInterface>hardware_interface/EffortJointInterface</hardwareInterface>
    </joint>
    <actuator name="head_pan_motor">
      <hardwareInterface>hardware_interface/EffortJointInterface</hardwareInterface>
      <mechanicalReduction>1</mechanicalReduction>
    </actuator>
  </transmission>
  <transmission name="head_tilt_transmission">
    <type>transmission_interface/SimpleTransmission</type>
    <joint name="head_tilt">
      <hardwareInterface>hardware_interface/EffortJointInterface</hardwareInterface>
    </joint>
    <actuator name="head_tilt_motor">
      <hardwareInterface>hardware_interface/EffortJointInterface</hardwareInterface>
      <mechanicalReduction>10</mechanicalReduction>
    </actuator>
  </transmission>
  <gazebo reference="kinect_base">
    <sensor name="kinect_justina" type="depth">
      <update_rate>30</update_rate>
      <visualize>true</visualize>
      <always_on>1</always_on>
      <camera>
        <horizontal_fov>1.047198</horizontal_fov>
        <image>
          <width>640</width>
          <height>480</height>
          <format>B8G8R8</format>
        </image>
      </camera>
      <plugin filename="libgazebo_ros_openni_kinect.so" name="kinect_controller">
        <baseline>0.2</baseline>
        <alwaysOn>true</alwaysOn>
        <updateRate>0.0</updateRate>
        <cameraName>kinect</cameraName>
        <imageTopicName>rgb/image_raw</imageTopicName>
        <cameraInfoTopicName>rgb/camera_info</cameraInfoTopicName>
        <depthImageTopicName>depth/image_raw</depthImageTopicName>
        <depthImageCameraInfoTopicName>depth/camera_info</depthImageCameraInfoTopicName>
        <pointCloudTopicName>points</pointCloudTopicName>
        <frameName>kinect_link</frameName>
        <pointCloudCutoffMax>3.5</pointCloudCutoffMax>
        <pointCloudCutoff>0.5</pointCloudCutoff>
        <CxPrime>0</CxPrime>
        <Cx>0</Cx>
        <Cy>0</Cy>
        <focalLength>0</focalLength>
        <hackBaseline>0</hackBaseline>
      </plugin>
    </sensor>
  </gazebo>
  <gazebo reference="head_link1">
    <material>Gazebo/SkyBlue</material>
  </gazebo>
  <gazebo reference="head_link2">
    <material>Gazebo/SkyBlue</material>
  </gazebo>
  <gazebo reference="neck_link">
    <material>Gazebo/Black</material>
  </gazebo>
  <gazebo reference="kinect_base">
    <material>Gazebo/Black</material>
  </gazebo>
  <gazebo reference="kinect_link">
    <material>Gazebo/Black</material>
  </gazebo>
  <!--HEAD LINKS AND JOINTS-->
  <link name="head_link1">
    <visual>
      <origin rpy="0 0 0" xyz="-0.01 0 0.03"/>
      <geometry>
        <box size="0.06 0.04 0.04"/>
      </geometry>
      <material name="blue"/>
    </visual>
    <collision>
      <origin rpy="0 0 0" xyz="-0.01 0 0.03"/>
      <geometry>
        <box size="0.06 0.04 0.04"/>
      </geometry>
    </collision>
    <inertial>
      <origin rpy="0 0 0" xyz="0.0 0 0.0"/>
      <mass value="0.15"/>
      <inertia ixx="0.00052" ixy="0" ixz="0" iyy="0.00052" iyz="0" izz="0.00004"/>
    </inertial>
  </link>
  <link name="head_link2">
    <visual>
      <origin rpy="0 0 0" xyz="0.0 0 0.035"/>
      <geometry>
        <box size="0.04 0.04 0.06"/>
      </geometry>
      <material name="orange"/>
    </visual>
    <collision>
      <origin rpy="0 0 0" xyz="0.0 0 0.035"/>
      <geometry>
        <box size="0.04 0.04 0.06"/>
      </geometry>
    </collision>
    <inertial>
      <origin rpy="0 0 0" xyz="0.0 0 0.0"/>
      <mass value="0.15"/>
      <inertia ixx="0.00003125" ixy="0" ixz="0" iyy="0.00003125" iyz="0" izz="0.00003125"/>
    </inertial>
  </link>
  <joint name="head_pan" type="revolute">
    <origin rpy="0 0 0" xyz="0.0 0 0.05"/>
    <parent link="head_link1"/>
    <child link="head_link2"/>
    <axis xyz="0 0 1"/>
    <dynamics damping="0.1"/>
    <limit effort="6.0" lower="-3.14" upper="3.14" velocity="3.0"/>
  </joint>
  <link name="neck_link">
    <visual>
      <origin rpy="0 0 0" xyz="0 0 0.035"/>
      <geometry>
        <box size="0.02 0.02 0.02"/>
      </geometry>
      <material name="black"/>
    </visual>
    <collision>
      <origin rpy="0 0 0" xyz="0 0 0.035"/>
      <geometry>
        <box size="0.02 0.02 0.02"/>
      </geometry>
    </collision>
    <inertial>
      <origin rpy="0 0 0" xyz="0.0 0 0.0"/>
      <mass value="0.15"/>
      <inertia ixx="0.00006205" ixy="0" ixz="0" iyy="0.000555" iyz="0" izz="0.0005776"/>
    </inertial>
  </link>
  <joint name="head_tilt" type="revolute">
    <origin rpy="0 0 0" xyz="0.0 0 0.06"/>
    <parent link="head_link2"/>
    <child link="neck_link"/>
    <axis xyz="0 -1 0"/>
    <dynamics damping="0.1"/>
    <limit effort="6.0" lower="-1.2" upper="1.0" velocity="3.0"/>
  </joint>
  <link name="kinect_base">
    <visual>
      <origin rpy="0 0 0" xyz="0 0 0"/>
      <geometry>
        <box size=" 0.058 0.207 0.04"/>
      </geometry>
      <material name="black"/>
    </visual>
    <collision>
      <origin rpy="0 0 0" xyz="0 0 0"/>
      <geometry>
        <box size=" 0.058 0.207 0.04"/>
      </geometry>
    </collision>
    <inertial>
      <origin rpy="0 0 0" xyz="0.0 0 0.0"/>
      <mass value="0.15"/>
      <inertia ixx="0.00006205" ixy="0" ixz="0" iyy="0.000555" iyz="0" izz="0.0005776"/>
    </inertial>
  </link>
  <joint name="kinect_base_connect" type="fixed">
    <origin rpy="0 0 0" xyz="0 0 0.065"/>
    <parent link="neck_link"/>
    <child link="kinect_base"/>
  </joint>
  <link name="kinect_link"/>
  <joint name="kinect_connect" type="fixed">
    <origin rpy="-1.5708 0 -1.5708" xyz="0 0 0"/>
    <parent link="kinect_base"/>
    <child link="kinect_link"/>
  </joint>
  <joint name="torso_connect" type="fixed">
    <origin rpy="0 0 0" xyz="0 0 0.9"/>
    <parent link="base_link"/>
    <child link="torso_link"/>
  </joint>
  <joint name="shoulder_left_connect" type="fixed">
    <origin rpy="0 0 0" xyz="0 0.195 -0.08"/>
    <parent link="spine_link"/>
    <child link="shoulders_left_link"/>
  </joint>
  <joint name="shoulder_right_connect" type="fixed">
    <origin rpy="0 0 0" xyz="0 -0.195 -0.08"/>
    <parent link="spine_link"/>
    <child link="shoulders_right_link"/>
  </joint>
  <joint name="spine_head_connect" type="fixed">
    <origin rpy="0 0 0" xyz="0 0 0.05"/>
    <parent link="spine_link"/>
    <child link="head_link1"/>
  </joint>
</robot>

