<?xml version="1.0" encoding="utf-8"?>
<robot name="justina_simple">
    <!--
    Importacion de todos los elementos de personalizacion de Gazebo
  -->
  <gazebo>
    <plugin filename="libgazebo_ros_control.so" name="ros_control">
      <robotNamespace>/justina_simple</robotNamespace>
    </plugin>
  </gazebo>
  <gazebo reference="base_link">
    <material>Gazebo/Blue</material>
  </gazebo>
  <gazebo reference="laser_link">
    <material>Gazebo/Black</material>
  </gazebo>
  <gazebo reference="wheel_left">
    <material>Gazebo/Black</material>
  </gazebo>
  <gazebo reference="wheel_right">
    <material>Gazebo/Black</material>
  </gazebo>
  <gazebo reference="wheel_front">
    <material>Gazebo/Black</material>
  </gazebo>
  <gazebo reference="wheel_back">
    <material>Gazebo/Black</material>
  </gazebo>
  <gazebo reference="spine_link">
    <material>Gazebo/SkyBlue</material>
  </gazebo>
  <gazebo reference="waist_link">
    <material>Gazebo/Grey</material>
  </gazebo>
  <gazebo reference="shoulders_link">
    <material>Gazebo/Red</material>
  </gazebo>
  <gazebo reference="shoulders_left_link">
    <material>Gazebo/Orange</material>
  </gazebo>
  <gazebo reference="shoulders_right_link">
    <material>Gazebo/Orange</material>
  </gazebo>
  <gazebo reference="left_arm_link1">
    <material>Gazebo/Orange</material>
  </gazebo>
  <gazebo reference="left_arm_link2">
    <material>Gazebo/Orange</material>
  </gazebo>
  <gazebo reference="left_arm_link3">
    <material>Gazebo/Orange</material>
  </gazebo>
  <gazebo reference="left_arm_link4">
    <material>Gazebo/Orange</material>
  </gazebo>
  <gazebo reference="left_arm_link5">
    <material>Gazebo/Orange</material>
  </gazebo>
  <gazebo reference="left_arm_link6">
    <material>Gazebo/Orange</material>
  </gazebo>
  <gazebo reference="left_arm_link7">
    <material>Gazebo/Orange</material>
  </gazebo>
  <gazebo reference="left_arm_grip_center">
    <material>Gazebo/Orange</material>
  </gazebo>
  <gazebo reference="left_arm_grip_left">
    <material>Gazebo/Orange</material>
  </gazebo>
  <gazebo reference="left_arm_grip_right">
    <material>Gazebo/Orange</material>
  </gazebo>
  <gazebo reference="right_arm_link1">
    <material>Gazebo/Orange</material>
  </gazebo>
  <gazebo reference="right_arm_link2">
    <material>Gazebo/Orange</material>
  </gazebo>
  <gazebo reference="right_arm_link3">
    <material>Gazebo/Orange</material>
  </gazebo>
  <gazebo reference="right_arm_link4">
    <material>Gazebo/Orange</material>
  </gazebo>
  <gazebo reference="right_arm_link5">
    <material>Gazebo/Orange</material>
  </gazebo>
  <gazebo reference="right_arm_link6">
    <material>Gazebo/Orange</material>
  </gazebo>
  <gazebo reference="right_arm_link7">
    <material>Gazebo/Orange</material>
  </gazebo>
  <gazebo reference="right_arm_grip_center">
    <material>Gazebo/Orange</material>
  </gazebo>
  <gazebo reference="right_arm_grip_left">
    <material>Gazebo/Orange</material>
  </gazebo>
  <gazebo reference="right_arm_grip_right">
    <material>Gazebo/Orange</material>
  </gazebo>
  <gazebo reference="head_link1">
    <material>Gazebo/Blue</material>
  </gazebo>
  <gazebo reference="head_link2">
    <material>Gazebo/Orange</material>
  </gazebo>
  <gazebo reference="kinect_link">
    <material>Gazebo/Black</material>
  </gazebo>



  <!-- Import Rviz colors -->
  <material name="black">
    <color rgba="0.0 0.0 0.0 1.0"/>
  </material>
  <material name="blue">
    <color rgba="0.0 0.0 0.8 1.0"/>
  </material>
  <material name="green">
    <color rgba="0.0 0.8 0.0 1.0"/>
  </material>
  <material name="grey">
    <color rgba="0.2 0.2 0.2 1.0"/>
  </material>
  <material name="orange">
    <color rgba="1.0 0.423529411765 0.0392156862745 1.0"/>
  </material>
  <material name="brown">
    <color rgba="0.870588235294 0.811764705882 0.764705882353 1.0"/>
  </material>
  <material name="red">
    <color rgba="0.8 0.0 0.0 1.0"/>
  </material>
  <material name="white">
    <color rgba="1.0 1.0 1.0 1.0"/>
  </material>
  <!--
      BASE LINKS AND JOINTS
  -->
  <link name="base_link">
    <visual>
      <origin xyz="0 0 0.235" rpy="0 0 0"/>
      <geometry> <box size="0.42 0.42 0.2"/></geometry>
      <material name="blue"/>
    </visual>
    <collision>
      <origin xyz="0 0 0.235" rpy="0 0 0"/>
      <geometry> <box size="0.42 0.42 0.2"/></geometry>
    </collision>
   <inertial>
      <origin xyz="0 0 0" rpy="0 0 0"/>
      <mass value="3.0"/>
      <inertia
        ixx="0.0541" ixy="0.0" ixz="0.0"
        iyy="0.0541" iyz="0.0"
        izz="0.0882"/>
    </inertial>
  </link>

  <link name="laser_link">
    <visual>
      <origin xyz="0 0 0" rpy="0 0 0"/>
      <geometry> <box size="0.08 0.08 0.1"/></geometry>
      <material name="black"/>
    </visual>
    <collision>
      <origin xyz="0 0 0" rpy="0 0 0"/>
      <geometry> <box size="0.08 0.08 0.1"/></geometry>
    </collision>
   <inertial>
      <origin xyz="0 0 0" rpy="0 0 0"/>
      <mass value="0.1"/>
      <inertia
        ixx="0.000136667" ixy="0.0" ixz="0.0"
        iyy="0.000136667" iyz="0.0"
        izz="0.000106667"/>
    </inertial>
  </link>
  
  <joint name="laser_connect" type="fixed">
    <origin xyz="0.1 0 0.44" />
    <parent link="base_link"/>
    <child link="laser_link"/>
  </joint>

  <link name="wheel_left">
    <visual>
      <origin xyz="0 0 0" rpy="1.5708 0 0"/>
      <geometry><cylinder length="0.04" radius="0.06"/></geometry>
      <material name="gray"/>
    </visual>
    <collision>
      <origin xyz="0 0 0" rpy="1.5708 0 0"/>
      <geometry><cylinder length="0.04" radius="0.06"/></geometry>
    </collision>
    <inertial>
      <origin xyz="0 0 0" rpy="0 0 0"/>
      <mass value="0.25"/>
      <inertia
        ixx="0.000258333" ixy="0.0" ixz="0.0"
        iyy="0.000258333" iyz="0.0"
        izz="0.00045"/>
    </inertial>
  </link>
  
  <joint name="wheel_left_connect" type="fixed">
    <origin xyz="0 -0.24 0.065" />
    <parent link="base_link"/>
    <child link="wheel_left"/>
  </joint>
  
  
  <link name="wheel_right">
    <visual>
      <origin xyz="0 0 0" rpy="1.5708 0 0"/>
      <geometry><cylinder length="0.04" radius="0.06"/></geometry>
      <material name="black"/>
    </visual>
    <collision>
      <origin xyz="0 0 0" rpy="1.5708 0 0"/>
      <geometry><cylinder length="0.04" radius="0.06"/></geometry>
    </collision>
    <inertial>
      <origin xyz="0 0 0" rpy="0 0 0"/>
      <mass value="0.25"/>
      <inertia
        ixx="0.000258333" ixy="0.0" ixz="0.0"
        iyy="0.000258333" iyz="0.0"
        izz="0.00045"/>
    </inertial>
  </link>

  <joint name="wheel_right_connect" type="fixed">
    <origin xyz="0 0.24 0.065" /> 
    <parent link="base_link"/>
    <child link="wheel_right"/>
  </joint>
  
  <link name="wheel_front">
    <visual>
      <origin xyz="0 0 0" rpy="1.5708 0 0"/>
      <geometry><cylinder length="0.04" radius="0.06"/></geometry>
      <material name="black"/>
    </visual>
    <collision>
      <origin xyz="0 0 0" rpy="1.5708 0 0"/>
      <geometry><cylinder length="0.04" radius="0.06"/></geometry>
    </collision>
    <inertial>
      <origin xyz="0 0 0" rpy="0 0 0"/>
      <mass value="0.25"/>
      <inertia
        ixx="0.000258333" ixy="0.0" ixz="0.0"
        iyy="0.000258333" iyz="0.0"
        izz="0.00045"/>
    </inertial>
  </link>
  
  <joint name="wheel_front_connect" type="fixed">
    <origin xyz="0.24 0 0.065" rpy="0 0 1.5708"/> 
    <parent link="base_link"/>
    <child link="wheel_front"/>
  </joint>
  
  <link name="wheel_back">
    <visual>
      <origin xyz="0 0 0" rpy="1.5708 0 0"/>
      <geometry><cylinder length="0.04" radius="0.06"/></geometry>
      <material name="black"/>
    </visual>
    <collision>
      <origin xyz="0 0 0" rpy="1.5708 0 0"/>
      <geometry><cylinder length="0.04" radius="0.06"/></geometry>
    </collision>
    <inertial>
      <origin xyz="0 0 0" rpy="0 0 0"/>
      <mass value="0.25"/>
      <inertia
        ixx="0.000258333" ixy="0.0" ixz="0.0"
        iyy="0.000258333" iyz="0.0"
        izz="0.00045"/>
    </inertial>
  </link>
  
  <joint name="wheel_back_connect" type="fixed">
    <origin xyz="-0.24 0 0.065" rpy="0 0 1.5708"/> 
    <parent link="base_link"/>
    <child link="wheel_back"/>
  </joint>
  

  <!--
      SPINE LINKS AND JOINTS
  -->
  <link name="spine_link">
    <visual>
      <origin xyz= "0 0 -0.3" rpy="0 0 0"/>
      <geometry><box size="0.07 0.045 0.7"/></geometry>
      <material name="blue"/>
    </visual>
    <collision>
      <origin xyz= "0 0 -0.3" rpy="0 0 0"/>
      <geometry><box size="0.07 0.045 0.7"/></geometry>
    </collision>
    <inertial>
      <origin xyz="0 0 0" rpy="0 0 0"/>
      <mass value="0.25"/>
      <inertia
        ixx="0.01031" ixy="0.0" ixz="0.0"
        iyy="0.01025" iyz="0.0"
        izz="0.00014"/>
    </inertial>
  </link>

  <joint name="spine_connect" type="fixed"> 
      <origin xyz= "0.0 0 0.71" rpy="0 0 0"/>
      <parent link="base_link"/>
      <child link="spine_link"/>
  </joint>


  <!--
      WAIST LINKS AND JOINTS
  -->
  <link name="waist_link">
    <visual>
      <origin xyz= "0 0 -0.1" rpy="0 0 0"/>
      <geometry><cylinder length="0.06" radius="0.08"/></geometry>
      <material name="grey"/>
    </visual>
    <collision>
      <origin xyz= "0 0 -0.1" rpy="0 0 0"/>
      <geometry><cylinder length="0.06" radius="0.08"/></geometry>
    </collision>
    <visual>
      <origin xyz= "0 0 -0.04" rpy="0 0 0"/>
      <geometry><cylinder length="0.08" radius="0.04"/></geometry>
      <material name="grey"/>
    </visual>
    <collision>
      <origin xyz= "0 0 -0.04" rpy="0 0 0"/>
      <geometry><cylinder length="0.08" radius="0.04"/></geometry>
    </collision>
    <visual>
      <origin xyz= "0 0 0.075" rpy="0 0 0"/>
      <geometry><box size="0.055 0.08 0.15" /></geometry>
      <material name="grey"/>
    </visual>
    <collision>
      <origin xyz= "0 0 0.075" rpy="0 0 0"/>
      <geometry><box size="0.055 0.08 0.15" /></geometry>
    </collision>
    <visual>
      <origin xyz= "0 0 0.235" rpy="0 0 0"/>
      <geometry><cylinder length="0.17" radius="0.02"/></geometry>
      <material name="green"/>
    </visual>
    <collision>
      <origin xyz= "0 0 0.235" rpy="0 0 0"/>
      <geometry><cylinder length="0.17" radius="0.02"/></geometry>
    </collision>
    <inertial>
      <origin xyz="0 0 0" rpy="0 0 0"/>
      <mass value="2.25"/>
      <inertia
        ixx="0.00258333" ixy="0.0" ixz="0.0"
        iyy="0.00258333" iyz="0.0"
        izz="0.0045"/>
    </inertial>
  </link>

  <joint name="waist_connect" type="fixed">
    <origin xyz= "0 0 0.16" rpy="0 0 0"/>
    <parent link="spine_link"/>
    <child link="waist_link"/>
  </joint>

  <link name="shoulders_link">
    <visual>
      <origin xyz= "0 0 0" rpy="0 0 0"/>
      <geometry><box size="0.045 0.43 0.045"/></geometry>
      <material name="red"/>
    </visual>
    <collision>
      <origin xyz= "0 0 0" rpy="0 0 0"/>
      <geometry><box size="0.045 0.43 0.045"/></geometry>
    </collision>
    <inertial>
      <origin xyz="0 0 0" rpy="0 0 0"/>
      <mass value="2.25"/>
      <inertia
        ixx="0.00075" ixy="0.0" ixz="0.0"
        iyy="0.03504" iyz="0.0"
        izz="0.03504"/>
    </inertial>
  </link>
  <link name="shoulders_left_link">
    <visual>
      <origin xyz="0.035 0.085 0" rpy = "0 0 0"/>
      <geometry> 
        <box size = "0.081 0.108 0.04025"/> 
      </geometry>
      <material name = "la_material"><color rgba="1.0 0.5 0 1"/></material>
    </visual>
    <collision>
      <origin xyz="0.035 0.085 0" rpy = "0 0 0"/>
      <geometry> 
        <box size = "0.081 0.108 0.04025"/> 
      </geometry>
    </collision>
    <inertial>
      <origin xyz="0 0 0" rpy="0 0 0"/>
      <mass value="2.25"/>
      <inertia
        ixx="0.0015" ixy="0.0" ixz="0.0"
        iyy="0.002175" iyz="0.0"
        izz="0.003075"/>
    </inertial>
  </link>
  <link name="shoulders_right_link">
    <visual>
      <origin xyz="0.035 -0.085 0" rpy = "0 0 0"/>
      <geometry> 
        <box size = "0.08 0.1 0.04"/> 
      </geometry>
      <material name = "la_material"><color rgba="1.0 0.5 0 1"/></material>
    </visual>
    <collision>
      <origin xyz="0.035 -0.085 0" rpy = "0 0 0"/>
      <geometry> 
        <box size = "0.08 0.1 0.04"/> 
      </geometry>
    </collision>
    <inertial>
      <origin xyz="0 0 0" rpy="0 0 0"/>
      <mass value="2.25"/>
      <inertia
        ixx="0.0015" ixy="0.0" ixz="0.0"
        iyy="0.002175" iyz="0.0"
        izz="0.003075"/>
    </inertial>
  </link>
  
  <joint name="shoulders_connect" type="fixed">
    <origin xyz="0 0 0.36" rpy="0 1.5708 0"/>
    <parent link="waist_link"/>
    <child link="shoulders_link"/>
  </joint>
  <joint name="shoulders_left_connect" type="fixed">
    <origin xyz="0 0.145 0" rpy="0 0 0"/>
    <parent link="shoulders_link"/>
    <child link="shoulders_left_link"/>
  </joint>
  <joint name="shoulders_right_connect" type="fixed">
    <origin xyz="0 -0.145 0" rpy="0 0 0"/>
    <parent link="shoulders_link"/>
    <child link="shoulders_right_link"/>
  </joint>


  <!--
      LEFT ARM LINKS AND JOINTS
  -->
  <link name="left_arm_link1">
    <visual>
      <origin xyz="0.0401 -0.0135 0.0" rpy = "0 0 0"/> 
      <geometry>   
        <box size = "0.035 0.071 0.04"/> 
      </geometry>
      <material name = "la_material"><color rgba="1.0 0.5 0 1"/></material>
    </visual>
    <collision>
      <origin xyz= "0.0401 -0.0135 0.0" rpy="0 0 0"/>
      <geometry>
        <box size="0.035 0.071 0.04"/>
      </geometry>
    </collision>
    <inertial>
      <origin xyz="0.0401 -0.0135 0.0"/>
      <mass value = "0.35" />
      <inertia ixx = "0.000215" iyy = "0.00025" izz = "0.000329" ixy = "0" ixz = "0" iyz = "0" />
    </inertial>
  </link>
  
  <link name="left_arm_link2">
    <visual>
      <origin xyz="0.103 0.0 0.0" rpy = "0 0 0"/> 
      <geometry>
        <box size = "0.21 0.038 0.035"/>
      </geometry>
      <material name = "la_material"><color rgba="1.0 0.5 0 1"/></material>
    </visual>
    <collision>
      <origin xyz= "0.103 0.0 0.0" rpy="0 0 0"/>
      <geometry>
        <box size="0.21 0.038 0.04"/>
      </geometry>
    </collision>
    <inertial>
      <origin xyz="0.103 0.0 0.0" rpy = "0 0 0"/>
      <mass value = "0.2" />
      <inertia ixx = "0.000761" iyy = "0.000053" izz = "0.000761" ixy = "0" ixz = "0" iyz = "0" />
    </inertial>
  </link>
  
  <link name="left_arm_link3">
    <visual>
      <origin xyz="0.245 0.0 0" rpy = "0 0 0"/>
      <geometry>
        <box size = "0.065 0.045 0.045"/>
      </geometry>
      <material name = "la_material"><color rgba="1.0 0.5 0 1"/></material>
    </visual>
    <collision>
      <origin xyz= "0.245 0 0" rpy="0 0 0"/>
      <geometry>
        <box size="0.065 0.045 0.045"/>
      </geometry>
    </collision>
    <inertial>
      <origin xyz="0.245 0 0" rpy = "0 0 0"/>
      <mass value = "0.18" />
      <inertia ixx = "0.0001218" iyy = "0.000075" izz = "0.0001218" ixy = "0" ixz = "0" iyz = "0" />
    </inertial>
  </link>
  
  <link name="left_arm_link4">
    <visual>
      <origin xyz="0.075 0.0 0.0" rpy = "0 0 0"/>
      <geometry> 
        <box size = "0.12 0.038 0.035"/> 
      </geometry>
      <material name = "la_material"><color rgba="1.0 0.5 0 1"/></material>
    </visual>
    <collision>
      <origin xyz= "0.075 0.0 0.0" rpy="0 0 0"/>
      <geometry>
        <box size="0.012 0.038 0.035"/>
      </geometry>
    </collision>
    <inertial>
      <origin xyz="0.09 0.0 0.0" rpy = "0 0 0"/>
      <mass value = "0.18" />
      <inertia ixx = "0.00051" iyy = "0.000048" izz = "0.00051" ixy = "0" ixz = "0" iyz = "0" />
    </inertial>
  </link>
  
  <link name="left_arm_link5">
    <visual>
      <origin xyz="0.165 0.0 0.0" rpy = "0 0 0"/>
      <geometry>
        <box size = "0.05 0.045 0.045"/>
      </geometry>
      <material name = "la_material"><color rgba="1.0 0.5 0 1"/></material>
    </visual>
    <collision>
      <origin xyz= "0.165 0.0 0.0" rpy="0 0 0"/>
      <geometry>
        <box size = "0.05 0.045 0.045"/>
      </geometry>
    </collision>
    <inertial>
      <origin xyz="0.165 0.0 0.0" rpy = "0 0 0"/>
      <mass value = "0.18" />
      <inertia ixx = "0.0000678" iyy = "0.000075" izz = "0.0000678" ixy = "0" ixz = "0" iyz = "0" />
    </inertial>
  </link>
  
  <link name="left_arm_link6">
    <visual>
      <origin xyz="0.022 0.0 0.0" rpy = "0 0 0"/>
      <geometry> 
        <box size = "0.075 0.038 0.035"/> 
      </geometry>
      <material name = "la_material"><color rgba="1.0 0.5 0 1"/></material>
    </visual>
    <collision>
      <origin xyz= "0.022 0.0 0.0" rpy="0 0 0"/>
      <geometry>
        <box size = "0.075 0.038 0.035"/>
      </geometry>
    </collision>
    <inertial>
      <origin xyz="0.022 0.0 0.0" rpy = "0 0 0"/>
      <mass value = "0.15" />
      <inertia ixx = "0.000145" iyy = "0.00004" izz = "0.000145" ixy = "0" ixz = "0" iyz = "0" />
    </inertial>
  </link>
  
  <link name="left_arm_link7">
    <visual>
      <origin xyz="0.083 0.0 0.0" rpy = "0 0 0"/>
      <geometry> 
        <box size = "0.045 0.045 0.045"/> 
      </geometry>
      <material name = "la_material"><color rgba="1.0 0.5 0 1"/></material>
    </visual>
    <collision>
      <origin xyz= "0.083 0 0.0" rpy="0 0 0"/>
      <geometry>
        <box size = "0.045 0.045 0.04"/>
      </geometry>
    </collision>
    <inertial>
      <origin xyz="0.1 0 0.0" rpy = "0 0 0"/>
      <mass value = "0.15" />
      <inertia ixx = "0.000065" iyy = "0.00004" izz = "0.000065" ixy = "0" ixz = "0" iyz = "0" />
    </inertial>
  </link>

  <link name="left_arm_grip_center">
    <visual>
      <origin xyz="0.0 0.0 0.0" rpy = "0 0 0"/>
      <geometry> 
        <box size = "0.04 0.1 0.04"/> 
      </geometry>
      <material name = "la_material"><color rgba="1.0 0.5 0 1"/></material>
    </visual>
    <collision>
      <origin xyz= "0.0 0 0.0" rpy="0 0 0"/>
      <geometry>
        <box size = "0.04 0.1 0.04"/>
      </geometry>
    </collision>
  </link>
  
  <link name="left_arm_grip_left">
    <visual>
      <origin xyz="0.065 0.0 0.0" rpy = "0 0 0"/>
      <geometry> 
        <box size = "0.1 0.015 0.03"/> 
      </geometry>
      <material name = "la_material"><color rgba="1.0 0.5 0 1"/></material>
    </visual>
    <collision>
      <origin xyz= "0.065 0 0.0" rpy="0 0 0"/>
      <geometry>
        <box size = "0.1 0.015 0.03"/>
      </geometry>
    </collision>
    <inertial>
      <origin xyz="0.1 0.0 0.0" rpy = "0 0 0"/>
      <mass value = "0.15" />
      <inertia ixx = "0.00022" iyy = "0.000014" izz = "0.0004925" ixy = "0" ixz = "0" iyz = "0" />
    </inertial>
  </link>
  
  <link name="left_arm_grip_right">
    <visual>
      <origin xyz="0.065 0.0 0.0" rpy = "0 0 0"/>
      <geometry> 
        <box size = "0.1 0.015 0.03"/> 
      </geometry>
      <material name = "la_material"><color rgba="1.0 0.5 0 1"/></material>
    </visual>
    <collision>
      <origin xyz= "0.065 0 0.0" rpy="0 0 0"/>
      <geometry>
        <box size = "0.1 0.015 0.03"/>
      </geometry>
    </collision>
    <inertial>
      <origin xyz="0.1 0 0.0" rpy = "0 0 0"/>
      <mass value = "0.15" />
      <inertia ixx = "0.00022" iyy = "0.000014" izz = "0.0004925" ixy = "0" ixz = "0" iyz = "0"/>
    </inertial>
  </link>
  
  <joint name="la_1_joint" type="revolute"> 
    <origin xyz="0.055 0.08 0" rpy="0 0 0"/>
    <parent link="shoulders_left_link"/>
    <child link="left_arm_link1"/>
    <axis xyz="0 -1 0" />
    <dynamics damping ="0.5" />
    <limit effort="1000" velocity="10" lower="-3.0" upper="3.0"/>
  </joint>
  <joint name="la_2_joint" type="revolute">
    <origin xyz="0.0638 0 0" rpy="0 0 0"/>
    <parent link="left_arm_link1"/>
    <child link="left_arm_link2"/>
    <axis xyz="0 0 -1" />
    <dynamics damping ="0.5" />
    <limit effort="1000" velocity="10" lower="-3.0" upper="3.0"/>
  </joint>
  <joint name="la_3_joint" type="revolute">
    <origin xyz="0.0 0 0" rpy="0 0 0"/>
    <parent link="left_arm_link2"/>
    <child link="left_arm_link3"/>
    <axis xyz="1 0 0" />
    <dynamics damping ="0.5" />
    <limit effort="1000" velocity="10" lower="-3.0" upper="3.0"/>
  </joint>
  <joint name="la_4_joint" type="revolute">
    <origin xyz="0.27 0 0" rpy="0 0 0"/>
    <parent link="left_arm_link3"/>
    <child link="left_arm_link4"/>
    <axis xyz="0 -1 0" />
    <dynamics damping ="0.5" />
    <limit effort="1000" velocity="10" lower="-3.0" upper="3.0"/>
  </joint>
  <joint name="la_5_joint" type="revolute">
    <origin xyz="0.0 0 0" rpy="0 0 0"/>
    <parent link="left_arm_link4"/>
    <child link="left_arm_link5"/>
    <axis xyz="1 0 0" />
    <dynamics damping ="0.5" />
    <limit effort="1000" velocity="10" lower="-3.0" upper="3.0"/>
  </joint>
  <joint name="la_6_joint" type="revolute">
    <origin xyz="0.2126 0 0" rpy="0 0 0"/>
    <parent link="left_arm_link5"/>
    <child link="left_arm_link6"/>
    <axis xyz="0 -1 0" />
    <dynamics damping ="0.5" />
    <limit effort="1000" velocity="10" lower="-3.0" upper="3.0"/>
  </joint>
  <joint name="la_7_joint" type="revolute">
    <origin xyz="0.0 0 0" rpy="0 0 0"/>
    <parent link="left_arm_link6"/>
    <child link="left_arm_link7"/>
    <axis xyz="1 0 0" />
    <dynamics damping ="0.5" />
    <limit effort="1000" velocity="10" lower="-3.0" upper="3.0"/>
  </joint>
  <joint name="la_grip_center_joint" type="fixed">
    <origin xyz="0.13 0 0" rpy="0 0 0"/>
    <parent link="left_arm_link7"/> 
    <child link="left_arm_grip_center"/> 
  </joint>
  <joint name="la_grip_left" type="fixed">
    <origin xyz="0 -0.04 0" rpy="0 0 0"/>
    <parent link="left_arm_grip_center"/> 
    <child link="left_arm_grip_left"/> 
  </joint>
  <joint name="la_grip_right" type="fixed">
    <origin xyz="0 0.04 0" rpy="0 0 0"/>
    <parent link="left_arm_grip_center"/> 
    <child link="left_arm_grip_right"/> 
  </joint>


  <!--
      RIGHT ARM LINKS AND JOINTS
  -->
  <link name="right_arm_link1">
    <visual>
      <origin xyz="0.0403 0.015 0.0" rpy = "0 0 0"/> 
      <geometry>   
        <box size = "0.07 0.08 0.05"/> 
      </geometry>
      <material name = "ra_material"><color rgba="1.0 0.5 0 1"/></material>
    </visual>
    <collision>
      <origin xyz= "0.0403 0.015 0.0" rpy="0 0 0"/>
      <geometry>
        <box size = "0.07 0.08 0.05"/>
      </geometry>
    </collision>
    <inertial>
      <origin xyz="0.0403 0.015 0.0"/>
      <mass value = "0.35" />
      <inertia ixx = "0.000215" iyy = "0.00025" izz = "0.000329" ixy = "0" ixz = "0" iyz = "0" />
    </inertial>

  </link>
  
  <link name="right_arm_link2">
    <visual>
      <origin xyz="0.105 0.0 0.0" rpy = "0 0 0"/> 
      <geometry>
        <box size = "0.21 0.04 0.04"/>
      </geometry>
      <material name = "ra_material"><color rgba="1.0 0.5 0 1"/></material>
    </visual>
    <collision>
      <origin xyz= "0.105 0.0 0.0" rpy="0 0 0"/>
      <geometry>
        <box size = "0.21 0.04 0.04"/>
      </geometry>
    </collision>
    <inertial>
      <origin xyz="0.105 0.0 0.0" rpy = "0 0 0"/>
      <mass value = "0.2" />
      <inertia ixx = "0.000761" iyy = "0.000053" izz = "0.000761" ixy = "0" ixz = "0" iyz = "0" />
    </inertial>
  </link>
  
  <link name="right_arm_link3">
    <visual>
      <origin xyz="0.21 0 0" rpy = "0 0 0"/>
      <geometry> 
        <box size = "0.075 0.05 0.05"/> 
      </geometry>
      <material name = "ra_material"><color rgba="1.0 0.5 0 1"/></material>
    </visual>
    <collision>
      <origin xyz= "0.21 0 0" rpy="0 0 0"/>
      <geometry>
        <box size = "0.075 0.05 0.05"/>
      </geometry>
    </collision>
    <inertial>
      <origin xyz="0.21 0 0" rpy = "0 0 0"/>
      <mass value = "0.18" />
      <inertia ixx = "0.0001218" iyy = "0.000075" izz = "0.0001218" ixy = "0" ixz = "0" iyz = "0" />
    </inertial>
  </link>
  
  <link name="right_arm_link4">
    <visual>
      <origin xyz="0.09 0.0 0.0" rpy = "0 0 0"/>
      <geometry> 
        <box size = "0.18 0.04 0.04"/> 
      </geometry>
      <material name = "ra_material"><color rgba="1.0 0.5 0 1"/></material>
    </visual>
    <collision>
      <origin xyz= "0.09 0.0 0.0" rpy="0 0 0"/>
      <geometry>
        <box size = "0.18 0.04 0.04"/>
      </geometry>
    </collision>
    <inertial>
      <origin xyz="0.09 0.0 0.0" rpy = "0 0 0"/>
      <mass value = "0.18" />
      <inertia ixx = "0.00051" iyy = "0.000048" izz = "0.00051" ixy = "0" ixz = "0" iyz = "0"  />
    </inertial>
  </link>
  
  <link name="right_arm_link5">
    <visual>
      <origin xyz="0.18 0.0 0.0" rpy = "0 0 0"/>
      <geometry>
        <box size = "0.045 0.05 0.05"/>
      </geometry>
      <material name = "ra_material"><color rgba="1.0 0.5 0 1"/></material>
    </visual>
    <collision>
      <origin xyz= "0.18 0.0 0.0" rpy="0 0 0"/>
      <geometry>
        <box size = "0.045 0.05 0.05"/>
      </geometry>
    </collision>
    <inertial>
      <origin xyz="0.18 0.0 0.0" rpy = "0 0 0"/>
      <mass value = "0.18" />
      <inertia ixx = "0.0000678" iyy = "0.000075" izz = "0.0000678" ixy = "0" ixz = "0" iyz = "0" />
    </inertial>
  </link>
  
  <link name="right_arm_link6">
    <visual>
      <origin xyz="0.05 0.0 0.0" rpy = "0 0 0"/>
      <geometry> 
        <box size = "0.1 0.04 0.04"/> 
      </geometry>
      <material name = "ra_material"><color rgba="1.0 0.5 0 1"/></material>
    </visual>
    <collision>
      <origin xyz= "0.05 0.0 0.0" rpy="0 0 0"/>
      <geometry>
        <box size = "0.1 0.04 0.04"/>
      </geometry>
    </collision>
    <inertial>
      <origin xyz="0.05 0.0 0.0" rpy = "0 0 0"/>
      <mass value = "0.15" />
      <inertia ixx = "0.000145" iyy = "0.00004" izz = "0.000145" ixy = "0" ixz = "0" iyz = "0"/>
    </inertial>
  </link>
  
  <link name="right_arm_link7">
    <visual>
      <origin xyz="0.1 0 0.0" rpy = "0 0 0"/>
      <geometry> 
        <box size = "0.06 0.04 0.04"/> 
      </geometry>
      <material name = "ra_material"><color rgba="1.0 0.5 0 1"/></material>
    </visual>
    <collision>
      <origin xyz= "0.1 0 0.0" rpy="0 0 0"/>
      <geometry>
        <box size = "0.06 0.04 0.04"/>
      </geometry>
    </collision>
    <inertial>
      <origin xyz="0.1 0 0.0" rpy = "0 0 0"/>
      <mass value = "0.15" />
      <inertia ixx = "0.000065" iyy = "0.00004" izz = "0.000065" ixy = "0" ixz = "0" iyz = "0"  />
    </inertial>
  </link>

  <link name="right_arm_grip_center">
    <visual>
      <origin xyz="0.0 0 0.0" rpy = "0 0 0"/>
      <geometry> 
        <box size = "0.04 0.1 0.04"/> 
      </geometry>
      <material name = "ra_material"><color rgba="1.0 0.5 0 1"/></material>
    </visual>
    <collision>
      <origin xyz= "0.0 0 0.0" rpy="0 0 0"/>
      <geometry>
        <box size = "0.04 0.1 0.04"/>
      </geometry>
    </collision>
  </link>
  
  <link name="right_arm_grip_left">
    <visual>
      <origin xyz="0.065 0 0.0" rpy = "0 0 0"/>
      <geometry> 
        <box size = "0.13 0.015 0.03"/> 
      </geometry>
      <material name = "ra_material"><color rgba="1.0 0.5 0 1"/></material>
    </visual>
    <collision>
      <origin xyz= "0.065 0 0.0" rpy="0 0 0"/>
      <geometry>
        <box size = "0.13 0.015 0.03"/>
      </geometry>
    </collision>
    <inertial>
      <origin xyz="0.1 0 0.0" rpy = "0 0 0"/>
      <mass value = "0.15" />
      <inertia ixx = "0.00022" iyy = "0.000014" izz = "0.0004925" ixy = "0" ixz = "0" iyz = "0" />
    </inertial>
  </link>
  
  <link name="right_arm_grip_right">
    <visual>
      <origin xyz="0.065 0 0.0" rpy = "0 0 0"/>
      <geometry> 
        <box size = "0.13 0.015 0.03"/> 
      </geometry>
      <material name = "ra_material"><color rgba="1.0 0.5 0 1"/></material>
    </visual>
    <collision>
      <origin xyz= "0.065 0 0.0" rpy="0 0 0"/>
      <geometry>
        <box size = "0.13 0.015 0.03"/>
      </geometry>
    </collision>
    <inertial>
      <origin xyz="0.1 0 0.0" rpy = "0 0 0"/>
      <mass value = "0.15" />
      <inertia ixx = "0.00022" iyy = "0.000014" izz = "0.0004925" ixy = "0" ixz = "0" iyz = "0" />
    </inertial>
  </link>
  
  <joint name="ra_1_joint" type="revolute"> 
    <origin xyz="0.055 -0.09 0" rpy="0 0 0"/>
    <parent link="shoulders_right_link"/>
    <child link="right_arm_link1"/>
    <axis xyz="0 -1 0" />
    <dynamics damping ="0.5" />
    <limit effort="1000" velocity="10" lower="-3.0" upper="3.0"/>
  </joint>
  <joint name="ra_2_joint" type="revolute">
    <origin xyz="0.0603 0 0" rpy="0 0 0"/>
    <parent link="right_arm_link1"/>
    <child link="right_arm_link2"/>
    <axis xyz="0 0 -1" />
    <dynamics damping ="0.5" />
    <limit effort="1000" velocity="10" lower="-3.0" upper="3.0"/>
  </joint>
  <joint name="ra_3_joint" type="revolute">
    <origin xyz="0.0 0 0" rpy="0 0 0"/>
    <parent link="right_arm_link2"/>
    <child link="right_arm_link3"/>
    <axis xyz="1 0 0" />
    <dynamics damping ="0.5" />
    <limit effort="1000" velocity="10" lower="-3.0" upper="3.0"/>
  </joint>
  <joint name="ra_4_joint" type="revolute">
    <origin xyz="0.27 0 0" rpy="0 0 0"/>
    <parent link="right_arm_link3"/>
    <child link="right_arm_link4"/>
    <axis xyz="0 -1 0" />
    <dynamics damping ="0.5" />
    <limit effort="1000" velocity="10" lower="-3.0" upper="3.0"/>
  </joint>
  <joint name="ra_5_joint" type="revolute">
    <origin xyz="0.0 0 0" rpy="0 0 0"/>
    <parent link="right_arm_link4"/>
    <child link="right_arm_link5"/>
    <axis xyz="1 0 0" />
    <dynamics damping ="0.5" />
    <limit effort="1000" velocity="10" lower="-3.0" upper="3.0"/>
  </joint>
  <joint name="ra_6_joint" type="revolute">
    <origin xyz="0.2126 0 0" rpy="0 0 0"/>
    <parent link="right_arm_link5"/>
    <child link="right_arm_link6"/>
    <axis xyz="0 -1 0" />
    <dynamics damping ="0.5" />
    <limit effort="1000" velocity="10" lower="-3.0" upper="3.0"/>
  </joint>
  <joint name="ra_7_joint" type="revolute">
    <origin xyz="0.0 0 0" rpy="0 0 0"/>
    <parent link="right_arm_link6"/>
    <child link="right_arm_link7"/>
    <axis xyz="1 0 0" />
    <dynamics damping ="0.5" />
    <limit effort="1000" velocity="10" lower="-3.0" upper="3.0"/>
  </joint>
  <joint name="ra_grip_center_joint" type="fixed">
    <origin xyz="0.13 0 0" rpy="0 0 0"/>
    <parent link="right_arm_link7"/> 
    <child link="right_arm_grip_center"/> 
  </joint>
  <joint name="ra_grip_left" type="fixed">
    <origin xyz="0 -0.04 0" rpy="0 0 0"/>
    <parent link="right_arm_grip_center"/> 
    <child link="right_arm_grip_left"/> 
  </joint>
  <joint name="ra_grip_right" type="fixed">
    <origin xyz="0 0.04 0" rpy="0 0 0"/>
    <parent link="right_arm_grip_center"/> 
    <child link="right_arm_grip_right"/> 
  </joint>

  <!--
      HEAD LINKS AND JOINTS
  -->
  <link name="head_link1">
    <visual>
      <origin xyz= "0 0 -0.1" rpy="0 0 0"/>
      <geometry>
        <box size="0.04 0.04 0.2"/>
      </geometry>
      <material name="blue"/>
    </visual>
    <collision>
      <origin xyz= "0 0 -0.1" rpy="0 0 0"/>
      <geometry>
        <box size = "0.04 0.04 0.2"/>
      </geometry>
    </collision>
    <inertial>
      <origin xyz="0.0 0 0.0" rpy = "0 0 0"/>
      <mass value = "0.15" />
      <inertia ixx = "0.00052" iyy = "0.00052" izz = "0.00004" ixy = "0" ixz = "0" iyz = "0" />
    </inertial>
  </link>
  
  <joint name="pan_connect" type="revolute">
    <origin xyz="-0.1 0 0" rpy="0 -1.5708 0"/>
    <parent link="shoulders_link"/>
    <child link="head_link1"/>
    <axis xyz="0 0 1" />
    <dynamics damping ="0.1" />
    <limit effort="1000" velocity="10" lower="-3.0" upper="3.0"/>
  </joint>
  
  <link name="head_link2">
    <visual>
      <origin xyz= "0.0 0 0" rpy="1.5708 0 0"/>
      <geometry>
        <box size="0.03 0.03 0.03"/>
      </geometry>
      <material name="orange"/>
    </visual>
    <collision>
      <origin xyz= "0.0 0 0" rpy="0 0 0"/>
      <geometry>
        <box size = "0.03 0.03 0.03"/>
      </geometry>
    </collision>
    <inertial>
      <origin xyz="0.0 0 0.0" rpy = "0 0 0"/>
      <mass value = "0.15" />
      <inertia ixx = "0.00003125" iyy = "0.00003125" izz = "0.00003125" ixy = "0" ixz = "0" iyz = "0" />
    </inertial>
  </link>
  
  <joint name="tilt_connect" type="revolute">
    <origin xyz="0 0 0.055" rpy="0 0 0" />
    <parent link="head_link1"/>
    <child link="head_link2"/>
    <axis xyz="0 1 0" />
    <dynamics damping ="0.1" />
    <limit effort="1000" velocity="10" lower="-3.0" upper="3.0"/>
  </joint>
  
  <link name="kinect_link">
    <visual>
      <origin xyz="0 0 0" rpy="0 0 0"/>
      <geometry>
        <box size="0.058 0.207 0.04"/>
      </geometry>
      <material name="black"/>
    </visual>
    <collision>
      <origin xyz= "0 0 0" rpy="0 0 0"/>
      <geometry>
        <box size = "0.058 0.207 0.04"/>
      </geometry>
    </collision>
    <inertial>
      <origin xyz="0.0 0 0.0" rpy = "0 0 0"/>
      <mass value = "0.15" />
      <inertia ixx = "0.00006205" iyy = "0.000555" izz = "0.0005776" ixy = "0" ixz = "0" iyz = "0" />
    </inertial>
  </link>
  
  <joint name="kinect_connect" type="fixed">
    <origin xyz="0.0 0 0.05" rpy="0 0 0"/>
    <parent link="head_link2"/>
    <child link="kinect_link"/>
  </joint>

  <gazebo reference="kinect_link">
    <sensor name="kinect_camera" type="depth">
      <update_rate>30</update_rate>
      <visualize>true</visualize>
      <always_on>1</always_on>
      <camera>
  <horizontal_fov>1.047198</horizontal_fov>
  <image>
    <width>640</width>
    <height>480</height>
    <format>B8G8R8</format>
  </image>
      </camera>
      <plugin name="kinect_controller" filename="libgazebo_ros_openni_kinect.so">
  <baseline>0.2</baseline>
  <alwaysOn>true</alwaysOn>
  <updateRate>0.0</updateRate>
  <cameraName>kinect</cameraName>
  <imageTopicName>rgb/image_raw</imageTopicName>
  <cameraInfoTopicName>rgb/camera_info</cameraInfoTopicName>
  <depthImageTopicName>depth/image_raw</depthImageTopicName>
  <depthImageCameraInfoTopicName>depth/camera_info</depthImageCameraInfoTopicName>
  <pointCloudTopicName>points</pointCloudTopicName>
  <frameName>kinect_link</frameName>
  <pointCloudCutoffMax>3.5</pointCloudCutoffMax>
  <pointCloudCutoff>0.5</pointCloudCutoff>
  <CxPrime>0</CxPrime>
  <Cx>0</Cx>
  <Cy>0</Cy>
  <focalLength>0</focalLength>
  <hackBaseline>0</hackBaseline>
      </plugin>
    </sensor>
  </gazebo>
</robot>
